Workbook
Name AssistAttempt: Legend!$A$32
Name AssistError: Legend!$A$34
Name AssistSuccess: Legend!$A$33
Name AssistZero: Legend!$A$32
Name BlockError: Legend!$A$40
Name BlockHalf: Legend!$A$38
Name BlockKillError: Legend!$A$43
Name BlockKillHalf: Legend!$A$41
Name BlockKillSolo: Legend!$A$42
Name BlockSolo: Legend!$A$39
Name Cover: Legend!$A$50
Name Dig: Legend!$A$49
Name DigError: Legend!$A$51
Name GeneralError: Legend!$A$44
Name KillAttempt: Legend!$A$35
Name KillError: Legend!$A$36
Name KillSuccess: Legend!$A$37
Name OppKey: Legend!$A$26
Name Pass0: Legend!$A$45
Name Pass1: Legend!$A$46
Name Pass2: Legend!$A$47
Name Pass3: Legend!$A$48
Name ServeAce: Legend!$A$30
Name ServeError: Legend!$A$31
Name ServeIn: Legend!$A$29

Sheet Legend
A1: http://fs.ncaa.org/Docs/stats/Stats_Manuals/VB/2022.pdf
A3: Set #s
A4: 1
A5: 2
A6: 3
A7: 4
A8: 5
A10: Player Key | B10: Player Number | C10: Player
A11: s | B11: 1 | C11: Sam
A12: r | B12: 2 | C12: Reece
A13: c | B13: 3 | C13: Cameron
A14: l | B14: 5 | C14: Levi
A15: t | B15: 6 | C15: Tom
A16: z | B16: 7 | C16: Zach
A17: b | B17: 11 | C17: Bodhi
A18: k | B18: 12 | C18: Kaito
A19: h | B19: 13 | C19: Hayden
A20: j | B20: 23 | C20: Jayden
A21: m | B21: 14 | C21: Marcus
A22: h | B22: 15 | C22: Hugh
... A26: p | B26: 99 | C26: Opposition
A28: Action Key | B28: Action Category | C28: Action | D28: Definition
A29: si | B29: Serve | C29: In | D29: Serve went in, but was returned
A30: sa | B30: Serve | C30: Ace | D30: Serve was not returned by the opposition
A31: se | B31: Serve | C31: Error | D31: Service error
A32: aa | B32: Assist | C32: Attempt | D32: Did not result in a point
A33: as | B33: Assist | C33: Success | D33: Resulted in a point
A34: ae | B34: Assist | C34: Error | D34: The set directly resulted in an error
A35: ka | B35: Kill | C35: Attempt
A36: ke | B36: Kill | C36: Error
A37: ks | B37: Kill | C37: Success
A38: bh | B38: Block | C38: half | D38: Ball returned to opponent, but does not result in a point
A39: bs | B39: Block | C39: solo
A40: be | B40: Block | C40: error
A41: bkh | B41: Block Kill | C41: half | D41: Directly results in a point
A42: bks | B42: Block Kill | C42: solo | D42: Directly results in a point
A43: bke | B43: Block Kill | C43: error | D43: DNE?
A44: e | B44: Error | C44: General error
A45: p0 | B45: Pass | C45: 0
A46: p1 | B46: Pass | C46: 1
...

Sheet Data
A1: Set | B1: Raw Data | C1: Player | D1: Action | E1: Name | F1: Category | G1: Action
A2: 1 | C2: =IF(B2="","",IF(ISNUMBER(VALUE(_xlfn.TEXTBEFORE(B2," "))),_xlfn.XLOOKUP(VALUE(_xlfn.TEXTBEFORE(B2," ")),Legend!$B$11:$B$26,Legend!$A$11:$A$26,"NOT FOUND",0,1),_xlfn.TEXTBEFORE(B2," "))) | D2: =IF(B2="","",_xlfn.TEXTAFTER(B2," ")) | E2: =IF(C2="","",_xlfn.XLOOKUP(C2,Legend!$A$10:$A$26,Legend!$C$10:$C$26,"NOT FOUND",0,1)) | F2: =IF(C2="","",_xlfn.XLOOKUP(D2,Legend!$A$29:$A$118,Legend!$B$29:$B$118,"NOT FOUND",0,1)) | G2: =IF(C2="","",_xlfn.XLOOKUP(D2,Legend!$A$29:$A$118,Legend!$C$29:$C$118,"NOT FOUND",0,1))
A3: 1 | C3: =IF(B3="","",IF(ISNUMBER(VALUE(_xlfn.TEXTBEFORE(B3," "))),_xlfn.XLOOKUP(VALUE(_xlfn.TEXTBEFORE(B3," ")),Legend!$B$11:$B$26,Legend!$A$11:$A$26,"NOT FOUND",0,1),_xlfn.TEXTBEFORE(B3," "))) | D3: =IF(B3="","",_xlfn.TEXTAFTER(B3," ")) | E3: =IF(C3="","",_xlfn.XLOOKUP(C3,Legend!$A$10:$A$26,Legend!$C$10:$C$26,"NOT FOUND",0,1)) | F3: =IF(C3="","",_xlfn.XLOOKUP(D3,Legend!$A$29:$A$118,Legend!$B$29:$B$118,"NOT FOUND",0,1)) | G3: =IF(C3="","",_xlfn.XLOOKUP(D3,Legend!$A$29:$A$118,Legend!$C$29:$C$118,"NOT FOUND",0,1))
A4: 1 | C4: =IF(B4="","",IF(ISNUMBER(VALUE(_xlfn.TEXTBEFORE(B4," "))),_xlfn.XLOOKUP(VALUE(_xlfn.TEXTBEFORE(B4," ")),Legend!$B$11:$B$26,Legend!$A$11:$A$26,"NOT FOUND",0,1),_xlfn.TEXTBEFORE(B4," "))) | D4: =IF(B4="","",_xlfn.TEXTAFTER(B4," ")) | E4: =IF(C4="","",_xlfn.XLOOKUP(C4,Legend!$A$10:$A$26,Legend!$C$10:$C$26,"NOT FOUND",0,1)) | F4: =IF(C4="","",_xlfn.XLOOKUP(D4,Legend!$A$29:$A$118,Legend!$B$29:$B$118,"NOT FOUND",0,1)) | G4: =IF(C4="","",_xlfn.XLOOKUP(D4,Legend!$A$29:$A$118,Legend!$C$29:$C$118,"NOT FOUND",0,1))
A5: 1 | C5: =IF(B5="","",IF(ISNUMBER(VALUE(_xlfn.TEXTBEFORE(B5," "))),_xlfn.XLOOKUP(VALUE(_xlfn.TEXTBEFORE(B5," ")),Legend!$B$11:$B$26,Legend!$A$11:$A$26,"NOT FOUND",0,1),_xlfn.TEXTBEFORE(B5," "))) | D5: =IF(B5="","",_xlfn.TEXTAFTER(B5," ")) | E5: =IF(C5="","",_xlfn.XLOOKUP(C5,Legend!$A$10:$A$26,Legend!$C$10:$C$26,"NOT FOUND",0,1)) | F5: =IF(C5="","",_xlfn.XLOOKUP(D5,Legend!$A$29:$A$118,Legend!$B$29:$B$118,"NOT FOUND",0,1)) | G5: =IF(C5="","",_xlfn.XLOOKUP(D5,Legend!$A$29:$A$118,Legend!$C$29:$C$118,"NOT FOUND",0,1))
A6: 1 | C6: =IF(B6="","",IF(ISNUMBER(VALUE(_xlfn.TEXTBEFORE(B6," "))),_xlfn.XLOOKUP(VALUE(_xlfn.TEXTBEFORE(B6," ")),Legend!$B$11:$B$26,Legend!$A$11:$A$26,"NOT FOUND",0,1),_xlfn.TEXTBEFORE(B6," "))) | D6: =IF(B6="","",_xlfn.TEXTAFTER(B6," ")) | E6: =IF(C6="","",_xlfn.XLOOKUP(C6,Legend!$A$10:$A$26,Legend!$C$10:$C$26,"NOT FOUND",0,1)) | F6: =IF(C6="","",_xlfn.XLOOKUP(D6,Legend!$A$29:$A$118,Legend!$B$29:$B$118,"NOT FOUND",0,1)) | G6: =IF(C6="","",_xlfn.XLOOKUP(D6,Legend!$A$29:$A$118,Legend!$C$29:$C$118,"NOT FOUND",0,1))
A7: 1 | C7: =IF(B7="","",IF(ISNUMBER(VALUE(_xlfn.TEXTBEFORE(B7," "))),_xlfn.XLOOKUP(VALUE(_xlfn.TEXTBEFORE(B7," ")),Legend!$B$11:$B$26,Legend!$A$11:$A$26,"NOT FOUND",0,1),_xlfn.TEXTBEFORE(B7," "))) | D7: =IF(B7="","",_xlfn.TEXTAFTER(B7," ")) | E7: =IF(C7="","",_xlfn.XLOOKUP(C7,Legend!$A$10:$A$26,Legend!$C$10:$C$26,"NOT FOUND",0,1)) | F7: =IF(C7="","",_xlfn.XLOOKUP(D7,Legend!$A$29:$A$118,Legend!$B$29:$B$118,"NOT FOUND",0,1)) | G7: =IF(C7="","",_xlfn.XLOOKUP(D7,Legend!$A$29:$A$118,Legend!$C$29:$C$118,"NOT FOUND",0,1))
A8: 1 | C8: =IF(B8="","",IF(ISNUMBER(VALUE(_xlfn.TEXTBEFORE(B8," "))),_xlfn.XLOOKUP(VALUE(_xlfn.TEXTBEFORE(B8," ")),Legend!$B$11:$B$26,Legend!$A$11:$A$26,"NOT FOUND",0,1),_xlfn.TEXTBEFORE(B8," "))) | D8: =IF(B8="","",_xlfn.TEXTAFTER(B8," ")) | E8: =IF(C8="","",_xlfn.XLOOKUP(C8,Legend!$A$10:$A$26,Legend!$C$10:$C$26,"NOT FOUND",0,1)) | F8: =IF(C8="","",_xlfn.XLOOKUP(D8,Legend!$A$29:$A$118,Legend!$B$29:$B$118,"NOT FOUND",0,1)) | G8: =IF(C8="","",_xlfn.XLOOKUP(D8,Legend!$A$29:$A$118,Legend!$C$29:$C$118,"NOT FOUND",0,1))
A9: 1 | C9: =IF(B9="","",IF(ISNUMBER(VALUE(_xlfn.TEXTBEFORE(B9," "))),_xlfn.XLOOKUP(VALUE(_xlfn.TEXTBEFORE(B9," ")),Legend!$B$11:$B$26,Legend!$A$11:$A$26,"NOT FOUND",0,1),_xlfn.TEXTBEFORE(B9," "))) | D9: =IF(B9="","",_xlfn.TEXTAFTER(B9," ")) | E9: =IF(C9="","",_xlfn.XLOOKUP(C9,Legend!$A$10:$A$26,Legend!$C$10:$C$26,"NOT FOUND",0,1)) | F9: =IF(C9="","",_xlfn.XLOOKUP(D9,Legend!$A$29:$A$118,Legend!$B$29:$B$118,"NOT FOUND",0,1)) | G9: =IF(C9="","",_xlfn.XLOOKUP(D9,Legend!$A$29:$A$118,Legend!$C$29:$C$118,"NOT FOUND",0,1))
A10: 1 | C10: =IF(B10="","",IF(ISNUMBER(VALUE(_xlfn.TEXTBEFORE(B10," "))),_xlfn.XLOOKUP(VALUE(_xlfn.TEXTBEFORE(B10," ")),Legend!$B$11:$B$26,Legend!$A$11:$A$26,"NOT FOUND",0,1),_xlfn.TEXTBEFORE(B10," "))) | D10: =IF(B10="","",_xlfn.TEXTAFTER(B10," ")) | E10: =IF(C10="","",_xlfn.XLOOKUP(C10,Legend!$A$10:$A$26,Legend!$C$10:$C$26,"NOT FOUND",0,1)) | F10: =IF(C10="","",_xlfn.XLOOKUP(D10,Legend!$A$29:$A$118,Legend!$B$29:$B$118,"NOT FOUND",0,1)) | G10: =IF(C10="","",_xlfn.XLOOKUP(D10,Legend!$A$29:$A$118,Legend!$C$29:$C$118,"NOT FOUND",0,1))
A11: 1 | C11: =IF(B11="","",IF(ISNUMBER(VALUE(_xlfn.TEXTBEFORE(B11," "))),_xlfn.XLOOKUP(VALUE(_xlfn.TEXTBEFORE(B11," ")),Legend!$B$11:$B$26,Legend!$A$11:$A$26,"NOT FOUND",0,1),_xlfn.TEXTBEFORE(B11," "))) | D11: =IF(B11="","",_xlfn.TEXTAFTER(B11," ")) | E11: =IF(C11="","",_xlfn.XLOOKUP(C11,Legend!$A$10:$A$26,Legend!$C$10:$C$26,"NOT FOUND",0,1)) | F11: =IF(C11="","",_xlfn.XLOOKUP(D11,Legend!$A$29:$A$118,Legend!$B$29:$B$118,"NOT FOUND",0,1)) | G11: =IF(C11="","",_xlfn.XLOOKUP(D11,Legend!$A$29:$A$118,Legend!$C$29:$C$118,"NOT FOUND",0,1))
A12: 1 | C12: =IF(B12="","",IF(ISNUMBER(VALUE(_xlfn.TEXTBEFORE(B12," "))),_xlfn.XLOOKUP(VALUE(_xlfn.TEXTBEFORE(B12," ")),Legend!$B$11:$B$26,Legend!$A$11:$A$26,"NOT FOUND",0,1),_xlfn.TEXTBEFORE(B12," "))) | D12: =IF(B12="","",_xlfn.TEXTAFTER(B12," ")) | E12: =IF(C12="","",_xlfn.XLOOKUP(C12,Legend!$A$10:$A$26,Legend!$C$10:$C$26,"NOT FOUND",0,1)) | F12: =IF(C12="","",_xlfn.XLOOKUP(D12,Legend!$A$29:$A$118,Legend!$B$29:$B$118,"NOT FOUND",0,1)) | G12: =IF(C12="","",_xlfn.XLOOKUP(D12,Legend!$A$29:$A$118,Legend!$C$29:$C$118,"NOT FOUND",0,1))
A13: 1 | C13: =IF(B13="","",IF(ISNUMBER(VALUE(_xlfn.TEXTBEFORE(B13," "))),_xlfn.XLOOKUP(VALUE(_xlfn.TEXTBEFORE(B13," ")),Legend!$B$11:$B$26,Legend!$A$11:$A$26,"NOT FOUND",0,1),_xlfn.TEXTBEFORE(B13," "))) | D13: =IF(B13="","",_xlfn.TEXTAFTER(B13," ")) | E13: =IF(C13="","",_xlfn.XLOOKUP(C13,Legend!$A$10:$A$26,Legend!$C$10:$C$26,"NOT FOUND",0,1)) | F13: =IF(C13="","",_xlfn.XLOOKUP(D13,Legend!$A$29:$A$118,Legend!$B$29:$B$118,"NOT FOUND",0,1)) | G13: =IF(C13="","",_xlfn.XLOOKUP(D13,Legend!$A$29:$A$118,Legend!$C$29:$C$118,"NOT FOUND",0,1))
... A882: 1 | C882: =IF(B882="","",IF(ISNUMBER(VALUE(_xlfn.TEXTBEFORE(B882," "))),_xlfn.XLOOKUP(VALUE(_xlfn.TEXTBEFORE(B882," ")),Legend!$B$11:$B$26,Legend!$A$11:$A$26,"NOT FOUND",0,1),_xlfn.TEXTBEFORE(B882," "))) | D882: =IF(B882="","",_xlfn.TEXTAFTER(B882," ")) | E882: =IF(C882="","",_xlfn.XLOOKUP(C882,Legend!$A$10:$A$26,Legend!$C$10:$C$26,"NOT FOUND",0,1)) | F882: =IF(C882="","",_xlfn.XLOOKUP(D882,Legend!$A$29:$A$118,Legend!$B$29:$B$118,"NOT FOUND",0,1)) | G882: =IF(C882="","",_xlfn.XLOOKUP(D882,Legend!$A$29:$A$118,Legend!$C$29:$C$118,"NOT FOUND",0,1))
A883: 1
A884: 1
A885: 1
A886: 1
A887: 1
A888: 1
A889: 1
A890: 1
A891: 1
A892: 1
A893: 1
A894: 1
... A956: 1

Sheet Match Score
C2: SX Srv Aces | D2: =COUNTIFS(Data!$A:$A,"="&D$18,Data!$C:$C,"<>"&OppKey,Data!$D:$D,"="&ServeAce) -> 0 | E2: =COUNTIFS(Data!$A:$A,"="&E$18,Data!$C:$C,"<>"&OppKey,Data!$D:$D,"="&ServeAce) -> 0 | F2: =COUNTIFS(Data!$A:$A,"="&F$18,Data!$C:$C,"<>"&OppKey,Data!$D:$D,"="&ServeAce) -> 0 | G2: =COUNTIFS(Data!$A:$A,"="&G$18,Data!$C:$C,"<>"&OppKey,Data!$D:$D,"="&ServeAce) -> 0 | H2: =COUNTIFS(Data!$A:$A,"="&H$18,Data!$C:$C,"<>"&OppKey,Data!$D:$D,"="&ServeAce) -> 0
C3: SX Srv Errors | D3: =COUNTIFS(Data!$A:$A,"="&D$18,Data!$C:$C,"<>"&OppKey,Data!$D:$D,"="&ServeError) -> 0 | E3: =COUNTIFS(Data!$A:$A,"="&E$18,Data!$C:$C,"<>"&OppKey,Data!$D:$D,"="&ServeError) -> 0 | F3: =COUNTIFS(Data!$A:$A,"="&F$18,Data!$C:$C,"<>"&OppKey,Data!$D:$D,"="&ServeError) -> 0 | G3: =COUNTIFS(Data!$A:$A,"="&G$18,Data!$C:$C,"<>"&OppKey,Data!$D:$D,"="&ServeError) -> 0 | H3: =COUNTIFS(Data!$A:$A,"="&H$18,Data!$C:$C,"<>"&OppKey,Data!$D:$D,"="&ServeError) -> 0
C4: SX Pass Errors | D4: =COUNTIFS(Data!$A:$A,"="&D$18,Data!$C:$C,"<>"&OppKey,Data!$D:$D,"="&Pass0) -> 0 | E4: =COUNTIFS(Data!$A:$A,"="&E$18,Data!$C:$C,"<>"&OppKey,Data!$D:$D,"="&Pass0) -> 0 | F4: =COUNTIFS(Data!$A:$A,"="&F$18,Data!$C:$C,"<>"&OppKey,Data!$D:$D,"="&Pass0) -> 0 | G4: =COUNTIFS(Data!$A:$A,"="&G$18,Data!$C:$C,"<>"&OppKey,Data!$D:$D,"="&Pass0) -> 0 | H4: =COUNTIFS(Data!$A:$A,"="&H$18,Data!$C:$C,"<>"&OppKey,Data!$D:$D,"="&Pass0) -> 0
C5: SX Kills | D5: =COUNTIFS(Data!$A:$A,"="&D$18,Data!$C:$C,"<>"&OppKey,Data!$D:$D,"="&KillSuccess) -> 0 | E5: =COUNTIFS(Data!$A:$A,"="&E$18,Data!$C:$C,"<>"&OppKey,Data!$D:$D,"="&KillSuccess) -> 0 | F5: =COUNTIFS(Data!$A:$A,"="&F$18,Data!$C:$C,"<>"&OppKey,Data!$D:$D,"="&KillSuccess) -> 0 | G5: =COUNTIFS(Data!$A:$A,"="&G$18,Data!$C:$C,"<>"&OppKey,Data!$D:$D,"="&KillSuccess) -> 0 | H5: =COUNTIFS(Data!$A:$A,"="&H$18,Data!$C:$C,"<>"&OppKey,Data!$D:$D,"="&KillSuccess) -> 0
C6: SX Kill Err | D6: =COUNTIFS(Data!$A:$A,"="&D$18,Data!$C:$C,"<>"&OppKey,Data!$D:$D,"="&KillError) -> 0 | E6: =COUNTIFS(Data!$A:$A,"="&E$18,Data!$C:$C,"<>"&OppKey,Data!$D:$D,"="&KillError) -> 0 | F6: =COUNTIFS(Data!$A:$A,"="&F$18,Data!$C:$C,"<>"&OppKey,Data!$D:$D,"="&KillError) -> 0 | G6: =COUNTIFS(Data!$A:$A,"="&G$18,Data!$C:$C,"<>"&OppKey,Data!$D:$D,"="&KillError) -> 0 | H6: =COUNTIFS(Data!$A:$A,"="&H$18,Data!$C:$C,"<>"&OppKey,Data!$D:$D,"="&KillError) -> 0
C7: SX Set Err | D7: =COUNTIFS(Data!$A:$A,"="&D$18,Data!$C:$C,"<>"&OppKey,Data!$D:$D,"="&AssistError) -> 0 | E7: =COUNTIFS(Data!$A:$A,"="&E$18,Data!$C:$C,"<>"&OppKey,Data!$D:$D,"="&AssistError) -> 0 | F7: =COUNTIFS(Data!$A:$A,"="&F$18,Data!$C:$C,"<>"&OppKey,Data!$D:$D,"="&AssistError) -> 0 | G7: =COUNTIFS(Data!$A:$A,"="&G$18,Data!$C:$C,"<>"&OppKey,Data!$D:$D,"="&AssistError) -> 0 | H7: =COUNTIFS(Data!$A:$A,"="&H$18,Data!$C:$C,"<>"&OppKey,Data!$D:$D,"="&AssistError) -> 0
C8: SX Block Half | D8: {=COUNTIFS(Data!$A:$A,"="&D$18,Data!$C:$C,"<>"&OppKey,Data!$D:$D,"="&BlockKillHalf)} -> 0 | E8: {=COUNTIFS(Data!$A:$A,"="&E$18,Data!$C:$C,"<>"&OppKey,Data!$D:$D,"="&BlockKillHalf)} -> 0 | F8: {=COUNTIFS(Data!$A:$A,"="&F$18,Data!$C:$C,"<>"&OppKey,Data!$D:$D,"="&BlockKillHalf)} -> 0 | G8: {=COUNTIFS(Data!$A:$A,"="&G$18,Data!$C:$C,"<>"&OppKey,Data!$D:$D,"="&BlockKillHalf)} -> 0 | H8: {=COUNTIFS(Data!$A:$A,"="&H$18,Data!$C:$C,"<>"&OppKey,Data!$D:$D,"="&BlockKillHalf)} -> 0
C9: SX Block Solo | D9: =COUNTIFS(Data!$A:$A,"="&D$18,Data!$C:$C,"<>"&OppKey,Data!$D:$D,"="&BlockKillSolo) -> 0 | E9: =COUNTIFS(Data!$A:$A,"="&E$18,Data!$C:$C,"<>"&OppKey,Data!$D:$D,"="&BlockKillSolo) -> 0 | F9: =COUNTIFS(Data!$A:$A,"="&F$18,Data!$C:$C,"<>"&OppKey,Data!$D:$D,"="&BlockKillSolo) -> 0 | G9: =COUNTIFS(Data!$A:$A,"="&G$18,Data!$C:$C,"<>"&OppKey,Data!$D:$D,"="&BlockKillSolo) -> 0 | H9: =COUNTIFS(Data!$A:$A,"="&H$18,Data!$C:$C,"<>"&OppKey,Data!$D:$D,"="&BlockKillSolo) -> 0
C10: SX BHA Err | D10: =COUNTIFS(Data!$A:$A,"="&D$18,Data!$C:$C,"<>"&OppKey,Data!$D:$D,"="&GeneralError) -> 0 | E10: =COUNTIFS(Data!$A:$A,"="&E$18,Data!$C:$C,"<>"&OppKey,Data!$D:$D,"="&GeneralError) -> 0 | F10: =COUNTIFS(Data!$A:$A,"="&F$18,Data!$C:$C,"<>"&OppKey,Data!$D:$D,"="&GeneralError) -> 0 | G10: =COUNTIFS(Data!$A:$A,"="&G$18,Data!$C:$C,"<>"&OppKey,Data!$D:$D,"="&GeneralError) -> 0 | H10: =COUNTIFS(Data!$A:$A,"="&H$18,Data!$C:$C,"<>"&OppKey,Data!$D:$D,"="&GeneralError) -> 0
C12: Opp Aces | D12: =COUNTIFS(Data!$A:$A,"="&D$18,Data!$C:$C,"="&OppKey,Data!$D:$D,"="&ServeAce) -> 0 | E12: =COUNTIFS(Data!$A:$A,"="&E$18,Data!$C:$C,"="&OppKey,Data!$D:$D,"="&ServeAce) -> 0 | F12: =COUNTIFS(Data!$A:$A,"="&F$18,Data!$C:$C,"="&OppKey,Data!$D:$D,"="&ServeAce) -> 0 | G12: =COUNTIFS(Data!$A:$A,"="&G$18,Data!$C:$C,"="&OppKey,Data!$D:$D,"="&ServeAce) -> 0 | H12: =COUNTIFS(Data!$A:$A,"="&H$18,Data!$C:$C,"="&OppKey,Data!$D:$D,"="&ServeAce) -> 0
C13: Opp Srv Errors | D13: =COUNTIFS(Data!$A:$A,"="&D$18,Data!$C:$C,"="&OppKey,Data!$D:$D,"="&ServeError) -> 0 | E13: =COUNTIFS(Data!$A:$A,"="&E$18,Data!$C:$C,"="&OppKey,Data!$D:$D,"="&ServeError) -> 0 | F13: =COUNTIFS(Data!$A:$A,"="&F$18,Data!$C:$C,"="&OppKey,Data!$D:$D,"="&ServeError) -> 0 | G13: =COUNTIFS(Data!$A:$A,"="&G$18,Data!$C:$C,"="&OppKey,Data!$D:$D,"="&ServeError) -> 0 | H13: =COUNTIFS(Data!$A:$A,"="&H$18,Data!$C:$C,"="&OppKey,Data!$D:$D,"="&ServeError) -> 0
C14: Opp Kills | D14: =COUNTIFS(Data!$A:$A,"="&D$18,Data!$C:$C,"="&OppKey,Data!$D:$D,"="&KillSuccess) -> 0 | E14: =COUNTIFS(Data!$A:$A,"="&E$18,Data!$C:$C,"="&OppKey,Data!$D:$D,"="&KillSuccess) -> 0 | F14: =COUNTIFS(Data!$A:$A,"="&F$18,Data!$C:$C,"="&OppKey,Data!$D:$D,"="&KillSuccess) -> 0 | G14: =COUNTIFS(Data!$A:$A,"="&G$18,Data!$C:$C,"="&OppKey,Data!$D:$D,"="&KillSuccess) -> 0 | H14: =COUNTIFS(Data!$A:$A,"="&H$18,Data!$C:$C,"="&OppKey,Data!$D:$D,"="&KillSuccess) -> 0
C15: Opp Kill Err | D15: =COUNTIFS(Data!$A:$A,"="&D$18,Data!$C:$C,"="&OppKey,Data!$D:$D,"="&KillError) -> 0 | E15: =COUNTIFS(Data!$A:$A,"="&E$18,Data!$C:$C,"="&OppKey,Data!$D:$D,"="&KillError) -> 0 | F15: =COUNTIFS(Data!$A:$A,"="&F$18,Data!$C:$C,"="&OppKey,Data!$D:$D,"="&KillError) -> 0 | G15: =COUNTIFS(Data!$A:$A,"="&G$18,Data!$C:$C,"="&OppKey,Data!$D:$D,"="&KillError) -> 0 | H15: =COUNTIFS(Data!$A:$A,"="&H$18,Data!$C:$C,"="&OppKey,Data!$D:$D,"="&KillError) -> 0
C16: Opp BHA Err | D16: =COUNTIFS(Data!$A:$A,"="&D$18,Data!$C:$C,"="&OppKey,Data!$D:$D,"="&GeneralError) -> 0 | E16: =COUNTIFS(Data!$A:$A,"="&E$18,Data!$C:$C,"="&OppKey,Data!$D:$D,"="&GeneralError) -> 0 | F16: =COUNTIFS(Data!$A:$A,"="&F$18,Data!$C:$C,"="&OppKey,Data!$D:$D,"="&GeneralError) -> 0 | G16: =COUNTIFS(Data!$A:$A,"="&G$18,Data!$C:$C,"="&OppKey,Data!$D:$D,"="&GeneralError) -> 0 | H16: =COUNTIFS(Data!$A:$A,"="&H$18,Data!$C:$C,"="&OppKey,Data!$D:$D,"="&GeneralError) -> 0
C18: Set | D18: 1 | E18: 2 | F18: 3 | G18: 4 | H18: 5
C19: Team 1 | D19: =D2+D5+D8/2+D9+D13+D15+D16 -> 0 | E19: =E2+E5+E8/2+E9+E13+E15+E16 -> 0 | F19: =F2+F5+F8/2+F9+F13+F15+F16 -> 0 | G19: =G2+G5+G8/2+G9+G13+G15+G16 -> 0 | H19: =H2+H5+H8/2+H9+H13+H15+H16 -> 0
C20: Team 2 | D20: =D3+D4+D6+D7+D10+D12+D14 -> 0 | E20: =E3+E4+E6+E7+E10+E12+E14 -> 0 | F20: =F3+F4+F6+F7+F10+F12+F14 -> 0 | G20: =G3+G4+G6+G7+G10+G12+G14 -> 0 | H20: =H3+H4+H6+H7+H10+H12+H14 -> 0
C22: Team Stats | D22: Serving | I22: Defence | L22: Passing | Q22: Kills | U22: Set Assists | Y22: Blocks | AE22: Other
B23: Name Key | D23: In | E23: Aces | F23: Errors | G23: Total | H23: % | I23: Digs | J23: Covers | K23: Total | L23: 3 | M23: 2 | N23: 1 | O23: 0 | P23: Score | Q23: Attacks | R23: Kills | S23: Errors | T23: Hit Eff. | U23: Attempt | V23: Assists | W23: Errors | X23: Set Eff. | Y23: B Half | Z23: B Solo | AA23: B Score | AB23: BK Half | AC23: BK Solo | AD23: BK Score | AE23: Errors
C24: Team Total | D24: =SUM(D30:D40) -> 0 | E24: =SUM(E30:E40) -> 0 | F24: =SUM(F30:F40) -> 0 | G24: =SUM(D24:F24) -> 0 | H24: =IF((F24+E24+D24)=0,0,(D24+E24)/(F24+E24+D24)) -> 0 | I24: =SUM(I30:I40) -> 0 | J24: =SUM(J30:J40) -> 0 | K24: =SUM(K30:K40) -> 0 | L24: =SUM(L30:L40) -> 0 | M24: =SUM(M30:M40) -> 0 | N24: =SUM(N30:N40) -> 0 | O24: =SUM(O30:O40) -> 0 | P24: =SUM(P30:P40) -> 0 | ... S24: =SUM(S30:S40) -> 0 | T24: =IF((Q24+R24+S24)=0,0,(R24-S24)/(Q24+R24+S24)) -> 0 | U24: =SUM(U30:U40) -> 0 | V24: =SUM(V30:V40) -> 0 | W24: =SUM(W30:W40) -> 0 | X24: =IF((U24+V24+W24)=0,0,(V24)/(U24+V24+W24)) -> 0 | Y24: =SUM(Y30:Y39) -> 0 | Z24: =SUM(Z30:Z39) -> 0 | AA24: =SUM(AA30:AA39) -> 0 | AB24: =SUM(AB30:AB39) -> 0 | AC24: =SUM(AC30:AC39) -> 0 | AD24: =SUM(AD30:AD39) -> 0 | AE24: =SUM(AE30:AE40) -> 0
C25: % split per skill | D25: =D24/G24 -> #DIV/0! | E25: =E24/G24 -> #DIV/0! | F25: =F24/G24 -> #DIV/0! | L25: =L24/(L24+M24+N24+O24) -> #DIV/0! | M25: =M24/(L24+M24+N24+O24) -> #DIV/0! | N25: =N24/(L24+M24+N24+O24) -> #DIV/0! | O25: =O24/(L24+M24+N24+O24) -> #DIV/0! | Q25: =Q24/(Q24+R24+S24) -> #DIV/0! | R25: =R24/(Q24+R24+S24) -> #DIV/0! | S25: =S24/(S24+R24+Q24) -> #DIV/0! | U25: =U24/(U24+V24+W24) -> #DIV/0! | V25: =V24/(U24+V24+W24) -> #DIV/0! | W25: =W24/(U24+V24+W24) -> #DIV/0!
B26: =Legend!A26 -> p | C26: Opposition | D26: =COUNTIFS(Data!$C:$C,"="&B26,Data!$D:$D,"="&ServeIn) -> 0 | E26: =COUNTIFS(Data!$C:$C,"="&B26,Data!$D:$D,"="&ServeAce) -> 0 | F26: =COUNTIFS(Data!$C:$C,"="&B26,Data!$D:$D,"="&ServeError) -> 0 | G26: =SUM(D26:F26) -> 0 | H26: =IF((F26+E26+D26)=0,0,(D26+E26)/(F26+E26+D26)) -> 0 | Q26: =COUNTIFS(Data!$C:$C,"="&B26,Data!$D:$D,"="&KillAttempt) -> 0 | R26: =COUNTIFS(Data!$C:$C,"="&B26,Data!$D:$D,"="&KillSuccess) -> 0 | S26: =COUNTIFS(Data!$C:$C,"="&B26,Data!$D:$D,"="&KillError) -> 0 | AE26: =COUNTIFS(Data!$C:$C,"="&$B26,Data!$D:$D,"="&GeneralError) -> 0
C28: Player Stats | D28: Serving | I28: Defence | L28: Passing | Q28: Kills | U28: Set Assists | Y28: Blocks | AE28: Other
B29: Name Key | D29: In | E29: Aces | F29: Errors | G29: Total | H29: % | I29: Digs | J29: Covers | K29: Total | L29: 3 | M29: 2 | N29: 1 | O29: 0 | P29: Score | Q29: Attacks | R29: Kills | S29: Errors | T29: Hit Eff. | U29: Attempt | V29: Assists | W29: Errors | X29: Set Eff. | Y29: B Half | Z29: B Solo | AA29: B Score | AB29: BK Half | AC29: BK Solo | AD29: BK Score | AE29: Errors
B30: =Legend!A11 -> s | C30: =Legend!B11&" - "&Legend!C11 -> 1 - Sam | D30: =COUNTIFS(Data!$C:$C,"="&B30,Data!$D:$D,"="&ServeIn) -> 0 | E30: =COUNTIFS(Data!$C:$C,"="&B30,Data!$D:$D,"="&ServeAce) -> 0 | F30: =COUNTIFS(Data!$C:$C,"="&B30,Data!$D:$D,"="&ServeError) -> 0 | G30: =SUM(D30:F30) -> 0 | H30: =IF((D30+E30+F30)=0,0,(D30+E30)/(D30+E30+F30)) -> 0 | I30: =COUNTIFS(Data!$C:$C,"="&B30,Data!$D:$D,"="&Dig) -> 0 | J30: =COUNTIFS(Data!$C:$C,"="&B30,Data!$D:$D,"="&Cover) -> 0 | K30: =J30+I30 -> 0 | L30: =COUNTIFS(Data!$C:$C,"="&B30,Data!$D:$D,"="&Pass3) -> 0 | M30: =COUNTIFS(Data!$C:$C,"="&B30,Data!$D:$D,"="&Pass2) -> 0 | N30: =COUNTIFS(Data!$C:$C,"="&B30,Data!$D:$D,"="&Pass1) -> 0 | O30: =COUNTIFS(Data!$C:$C,"="&B30,Data!$D:$D,"="&Pass0) -> 0 | P30: =L30*3+M30*2+N30*1 -> 0 | Q30: =COUNTIFS(Data!$C:$C,"="&$B30,Data!$D:$D,"="&KillAttempt) -> 0 | R30: =COUNTIFS(Data!$C:$C,"="&$B30,Data!$D:$D,"="&KillSuccess) -> 0 | S30: =COUNTIFS(Data!$C:$C,"="&$B30,Data!$D:$D,"="&KillError) -> 0 | T30: =IF((Q30+R30+S30)=0,0,(R30-S30)/(Q30+R30+S30)) -> 0 | U30: =COUNTIFS(Data!$C:$C,"="&$B30,Data!$D:$D,"="&AssistZero) -> 0 | V30: =COUNTIFS(Data!$C:$C,"="&$B30,Data!$D:$D,"="&AssistSuccess) -> 0 | W30: =COUNTIFS(Data!$C:$C,"="&$B30,Data!$D:$D,"="&AssistError) -> 0 | X30: =IF((U30+V30+W30)=0,0,(V30)/(U30+V30+W30)) -> 0 | Y30: =COUNTIFS(Data!$C:$C,"="&$B30,Data!$D:$D,"="&BlockHalf) -> 0 | Z30: =COUNTIFS(Data!$C:$C,"="&$B30,Data!$D:$D,"="&BlockSolo) -> 0 | AA30: =Y30/2+Z30 -> 0 | AB30: {=COUNTIFS(Data!$C:$C,"="&$B30,Data!$D:$D,"="&BlockKillHalf)} -> 0 | AC30: =COUNTIFS(Data!$C:$C,"="&$B30,Data!$D:$D,"="&BlockKillSolo) -> 0 | AD30: =AB30*0.5+AC30 -> 0 | AE30: =COUNTIFS(Data!$C:$C,"="&$B30,Data!$D:$D,"="&GeneralError) -> 0
B31: =Legend!A12 -> r | C31: =Legend!B12&" - "&Legend!C12 -> 2 - Reece | D31: =COUNTIFS(Data!$C:$C,"="&B31,Data!$D:$D,"="&ServeIn) -> 0 | E31: =COUNTIFS(Data!$C:$C,"="&B31,Data!$D:$D,"="&ServeAce) -> 0 | F31: =COUNTIFS(Data!$C:$C,"="&B31,Data!$D:$D,"="&ServeError) -> 0 | G31: =SUM(D31:F31) -> 0 | H31: =IF((D31+E31+F31)=0,0,(D31+E31)/(D31+E31+F31)) -> 0 | I31: =COUNTIFS(Data!$C:$C,"="&B31,Data!$D:$D,"="&Dig) -> 0 | J31: =COUNTIFS(Data!$C:$C,"="&B31,Data!$D:$D,"="&Cover) -> 0 | K31: =J31+I31 -> 0 | L31: =COUNTIFS(Data!$C:$C,"="&B31,Data!$D:$D,"="&Pass3) -> 0 | M31: =COUNTIFS(Data!$C:$C,"="&B31,Data!$D:$D,"="&Pass2) -> 0 | N31: =COUNTIFS(Data!$C:$C,"="&B31,Data!$D:$D,"="&Pass1) -> 0 | O31: =COUNTIFS(Data!$C:$C,"="&B31,Data!$D:$D,"="&Pass0) -> 0 | P31: =L31*3+M31*2+N31*1 -> 0 | Q31: =COUNTIFS(Data!$C:$C,"="&$B31,Data!$D:$D,"="&KillAttempt) -> 0 | R31: =COUNTIFS(Data!$C:$C,"="&$B31,Data!$D:$D,"="&KillSuccess) -> 0 | S31: =COUNTIFS(Data!$C:$C,"="&$B31,Data!$D:$D,"="&KillError) -> 0 | T31: =IF((Q31+R31+S31)=0,0,(R31-S31)/(Q31+R31+S31)) -> 0 | U31: =COUNTIFS(Data!$C:$C,"="&$B31,Data!$D:$D,"="&AssistZero) -> 0 | V31: =COUNTIFS(Data!$C:$C,"="&$B31,Data!$D:$D,"="&AssistSuccess) -> 0 | W31: =COUNTIFS(Data!$C:$C,"="&$B31,Data!$D:$D,"="&AssistError) -> 0 | X31: =IF((U31+V31+W31)=0,0,(V31)/(U31+V31+W31)) -> 0 | Y31: =COUNTIFS(Data!$C:$C,"="&$B31,Data!$D:$D,"="&BlockHalf) -> 0 | Z31: =COUNTIFS(Data!$C:$C,"="&$B31,Data!$D:$D,"="&BlockSolo) -> 0 | AA31: =Y31/2+Z31 -> 0 | AB31: {=COUNTIFS(Data!$C:$C,"="&$B31,Data!$D:$D,"="&BlockKillHalf)} -> 0 | AC31: =COUNTIFS(Data!$C:$C,"="&$B31,Data!$D:$D,"="&BlockKillSolo) -> 0 | AD31: =AB31*0.5+AC31 -> 0 | AE31: =COUNTIFS(Data!$C:$C,"="&$B31,Data!$D:$D,"="&GeneralError) -> 0
B32: =Legend!A13 -> c | C32: =Legend!B13&" - "&Legend!C13 -> 3 - Cameron | D32: =COUNTIFS(Data!$C:$C,"="&B32,Data!$D:$D,"="&ServeIn) -> 0 | E32: =COUNTIFS(Data!$C:$C,"="&B32,Data!$D:$D,"="&ServeAce) -> 0 | F32: =COUNTIFS(Data!$C:$C,"="&B32,Data!$D:$D,"="&ServeError) -> 0 | G32: =SUM(D32:F32) -> 0 | H32: =IF((D32+E32+F32)=0,0,(D32+E32)/(D32+E32+F32)) -> 0 | I32: =COUNTIFS(Data!$C:$C,"="&B32,Data!$D:$D,"="&Dig) -> 0 | J32: =COUNTIFS(Data!$C:$C,"="&B32,Data!$D:$D,"="&Cover) -> 0 | K32: =J32+I32 -> 0 | L32: =COUNTIFS(Data!$C:$C,"="&B32,Data!$D:$D,"="&Pass3) -> 0 | M32: =COUNTIFS(Data!$C:$C,"="&B32,Data!$D:$D,"="&Pass2) -> 0 | N32: =COUNTIFS(Data!$C:$C,"="&B32,Data!$D:$D,"="&Pass1) -> 0 | O32: =COUNTIFS(Data!$C:$C,"="&B32,Data!$D:$D,"="&Pass0) -> 0 | P32: =L32*3+M32*2+N32*1 -> 0 | Q32: =COUNTIFS(Data!$C:$C,"="&$B32,Data!$D:$D,"="&KillAttempt) -> 0 | R32: =COUNTIFS(Data!$C:$C,"="&$B32,Data!$D:$D,"="&KillSuccess) -> 0 | S32: =COUNTIFS(Data!$C:$C,"="&$B32,Data!$D:$D,"="&KillError) -> 0 | T32: =IF((Q32+R32+S32)=0,0,(R32-S32)/(Q32+R32+S32)) -> 0 | U32: =COUNTIFS(Data!$C:$C,"="&$B32,Data!$D:$D,"="&AssistZero) -> 0 | V32: =COUNTIFS(Data!$C:$C,"="&$B32,Data!$D:$D,"="&AssistSuccess) -> 0 | W32: =COUNTIFS(Data!$C:$C,"="&$B32,Data!$D:$D,"="&AssistError) -> 0 | X32: =IF((U32+V32+W32)=0,0,(V32)/(U32+V32+W32)) -> 0 | Y32: =COUNTIFS(Data!$C:$C,"="&$B32,Data!$D:$D,"="&BlockHalf) -> 0 | Z32: =COUNTIFS(Data!$C:$C,"="&$B32,Data!$D:$D,"="&BlockSolo) -> 0 | AA32: =Y32/2+Z32 -> 0 | AB32: {=COUNTIFS(Data!$C:$C,"="&$B32,Data!$D:$D,"="&BlockKillHalf)} -> 0 | AC32: =COUNTIFS(Data!$C:$C,"="&$B32,Data!$D:$D,"="&BlockKillSolo) -> 0 | AD32: =AB32*0.5+AC32 -> 0 | AE32: =COUNTIFS(Data!$C:$C,"="&$B32,Data!$D:$D,"="&GeneralError) -> 0
B33: =Legend!A14 -> l | C33: =Legend!B14&" - "&Legend!C14 -> 5 - Levi | D33: =COUNTIFS(Data!$C:$C,"="&B33,Data!$D:$D,"="&ServeIn) -> 0 | E33: =COUNTIFS(Data!$C:$C,"="&B33,Data!$D:$D,"="&ServeAce) -> 0 | F33: =COUNTIFS(Data!$C:$C,"="&B33,Data!$D:$D,"="&ServeError) -> 0 | G33: =SUM(D33:F33) -> 0 | H33: =IF((D33+E33+F33)=0,0,(D33+E33)/(D33+E33+F33)) -> 0 | I33: =COUNTIFS(Data!$C:$C,"="&B33,Data!$D:$D,"="&Dig) -> 0 | J33: =COUNTIFS(Data!$C:$C,"="&B33,Data!$D:$D,"="&Cover) -> 0 | K33: =J33+I33 -> 0 | L33: =COUNTIFS(Data!$C:$C,"="&B33,Data!$D:$D,"="&Pass3) -> 0 | M33: =COUNTIFS(Data!$C:$C,"="&B33,Data!$D:$D,"="&Pass2) -> 0 | N33: =COUNTIFS(Data!$C:$C,"="&B33,Data!$D:$D,"="&Pass1) -> 0 | O33: =COUNTIFS(Data!$C:$C,"="&B33,Data!$D:$D,"="&Pass0) -> 0 | P33: =L33*3+M33*2+N33*1 -> 0 | Q33: =COUNTIFS(Data!$C:$C,"="&$B33,Data!$D:$D,"="&KillAttempt) -> 0 | R33: =COUNTIFS(Data!$C:$C,"="&$B33,Data!$D:$D,"="&KillSuccess) -> 0 | S33: =COUNTIFS(Data!$C:$C,"="&$B33,Data!$D:$D,"="&KillError) -> 0 | T33: =IF((Q33+R33+S33)=0,0,(R33-S33)/(Q33+R33+S33)) -> 0 | U33: =COUNTIFS(Data!$C:$C,"="&$B33,Data!$D:$D,"="&AssistZero) -> 0 | V33: =COUNTIFS(Data!$C:$C,"="&$B33,Data!$D:$D,"="&AssistSuccess) -> 0 | W33: =COUNTIFS(Data!$C:$C,"="&$B33,Data!$D:$D,"="&AssistError) -> 0 | X33: =IF((U33+V33+W33)=0,0,(V33)/(U33+V33+W33)) -> 0 | Y33: =COUNTIFS(Data!$C:$C,"="&$B33,Data!$D:$D,"="&BlockHalf) -> 0 | Z33: =COUNTIFS(Data!$C:$C,"="&$B33,Data!$D:$D,"="&BlockSolo) -> 0 | AA33: =Y33/2+Z33 -> 0 | AB33: {=COUNTIFS(Data!$C:$C,"="&$B33,Data!$D:$D,"="&BlockKillHalf)} -> 0 | AC33: =COUNTIFS(Data!$C:$C,"="&$B33,Data!$D:$D,"="&BlockKillSolo) -> 0 | AD33: =AB33*0.5+AC33 -> 0 | AE33: =COUNTIFS(Data!$C:$C,"="&$B33,Data!$D:$D,"="&GeneralError) -> 0
B34: =Legend!A15 -> t | C34: =Legend!B15&" - "&Legend!C15 -> 6 - Tom | D34: =COUNTIFS(Data!$C:$C,"="&B34,Data!$D:$D,"="&ServeIn) -> 0 | E34: =COUNTIFS(Data!$C:$C,"="&B34,Data!$D:$D,"="&ServeAce) -> 0 | F34: =COUNTIFS(Data!$C:$C,"="&B34,Data!$D:$D,"="&ServeError) -> 0 | G34: =SUM(D34:F34) -> 0 | H34: =IF((D34+E34+F34)=0,0,(D34+E34)/(D34+E34+F34)) -> 0 | I34: =COUNTIFS(Data!$C:$C,"="&B34,Data!$D:$D,"="&Dig) -> 0 | J34: =COUNTIFS(Data!$C:$C,"="&B34,Data!$D:$D,"="&Cover) -> 0 | K34: =J34+I34 -> 0 | L34: =COUNTIFS(Data!$C:$C,"="&B34,Data!$D:$D,"="&Pass3) -> 0 | M34: =COUNTIFS(Data!$C:$C,"="&B34,Data!$D:$D,"="&Pass2) -> 0 | N34: =COUNTIFS(Data!$C:$C,"="&B34,Data!$D:$D,"="&Pass1) -> 0 | O34: =COUNTIFS(Data!$C:$C,"="&B34,Data!$D:$D,"="&Pass0) -> 0 | P34: =L34*3+M34*2+N34*1 -> 0 | Q34: =COUNTIFS(Data!$C:$C,"="&$B34,Data!$D:$D,"="&KillAttempt) -> 0 | R34: =COUNTIFS(Data!$C:$C,"="&$B34,Data!$D:$D,"="&KillSuccess) -> 0 | S34: =COUNTIFS(Data!$C:$C,"="&$B34,Data!$D:$D,"="&KillError) -> 0 | T34: =IF((Q34+R34+S34)=0,0,(R34-S34)/(Q34+R34+S34)) -> 0 | U34: =COUNTIFS(Data!$C:$C,"="&$B34,Data!$D:$D,"="&AssistZero) -> 0 | V34: =COUNTIFS(Data!$C:$C,"="&$B34,Data!$D:$D,"="&AssistSuccess) -> 0 | W34: =COUNTIFS(Data!$C:$C,"="&$B34,Data!$D:$D,"="&AssistError) -> 0 | X34: =IF((U34+V34+W34)=0,0,(V34)/(U34+V34+W34)) -> 0 | Y34: =COUNTIFS(Data!$C:$C,"="&$B34,Data!$D:$D,"="&BlockHalf) -> 0 | Z34: =COUNTIFS(Data!$C:$C,"="&$B34,Data!$D:$D,"="&BlockSolo) -> 0 | AA34: =Y34/2+Z34 -> 0 | AB34: {=COUNTIFS(Data!$C:$C,"="&$B34,Data!$D:$D,"="&BlockKillHalf)} -> 0 | AC34: =COUNTIFS(Data!$C:$C,"="&$B34,Data!$D:$D,"="&BlockKillSolo) -> 0 | AD34: =AB34*0.5+AC34 -> 0 | AE34: =COUNTIFS(Data!$C:$C,"="&$B34,Data!$D:$D,"="&GeneralError) -> 0
B35: =Legend!A16 -> z | C35: =Legend!B16&" - "&Legend!C16 -> 7 - Zach | D35: =COUNTIFS(Data!$C:$C,"="&B35,Data!$D:$D,"="&ServeIn) -> 0 | E35: =COUNTIFS(Data!$C:$C,"="&B35,Data!$D:$D,"="&ServeAce) -> 0 | F35: =COUNTIFS(Data!$C:$C,"="&B35,Data!$D:$D,"="&ServeError) -> 0 | G35: =SUM(D35:F35) -> 0 | H35: =IF((D35+E35+F35)=0,0,(D35+E35)/(D35+E35+F35)) -> 0 | I35: =COUNTIFS(Data!$C:$C,"="&B35,Data!$D:$D,"="&Dig) -> 0 | J35: =COUNTIFS(Data!$C:$C,"="&B35,Data!$D:$D,"="&Cover) -> 0 | K35: =J35+I35 -> 0 | L35: =COUNTIFS(Data!$C:$C,"="&B35,Data!$D:$D,"="&Pass3) -> 0 | M35: =COUNTIFS(Data!$C:$C,"="&B35,Data!$D:$D,"="&Pass2) -> 0 | N35: =COUNTIFS(Data!$C:$C,"="&B35,Data!$D:$D,"="&Pass1) -> 0 | O35: =COUNTIFS(Data!$C:$C,"="&B35,Data!$D:$D,"="&Pass0) -> 0 | P35: =L35*3+M35*2+N35*1 -> 0 | Q35: =COUNTIFS(Data!$C:$C,"="&$B35,Data!$D:$D,"="&KillAttempt) -> 0 | R35: =COUNTIFS(Data!$C:$C,"="&$B35,Data!$D:$D,"="&KillSuccess) -> 0 | S35: =COUNTIFS(Data!$C:$C,"="&$B35,Data!$D:$D,"="&KillError) -> 0 | T35: =IF((Q35+R35+S35)=0,0,(R35-S35)/(Q35+R35+S35)) -> 0 | U35: =COUNTIFS(Data!$C:$C,"="&$B35,Data!$D:$D,"="&AssistZero) -> 0 | V35: =COUNTIFS(Data!$C:$C,"="&$B35,Data!$D:$D,"="&AssistSuccess) -> 0 | W35: =COUNTIFS(Data!$C:$C,"="&$B35,Data!$D:$D,"="&AssistError) -> 0 | X35: =IF((U35+V35+W35)=0,0,(V35)/(U35+V35+W35)) -> 0 | Y35: =COUNTIFS(Data!$C:$C,"="&$B35,Data!$D:$D,"="&BlockHalf) -> 0 | Z35: =COUNTIFS(Data!$C:$C,"="&$B35,Data!$D:$D,"="&BlockSolo) -> 0 | AA35: =Y35/2+Z35 -> 0 | AB35: {=COUNTIFS(Data!$C:$C,"="&$B35,Data!$D:$D,"="&BlockKillHalf)} -> 0 | AC35: =COUNTIFS(Data!$C:$C,"="&$B35,Data!$D:$D,"="&BlockKillSolo) -> 0 | AD35: =AB35*0.5+AC35 -> 0 | AE35: =COUNTIFS(Data!$C:$C,"="&$B35,Data!$D:$D,"="&GeneralError) -> 0
B36: =Legend!A17 -> b | C36: =Legend!B17&" - "&Legend!C17 -> 11 - Bodhi | D36: =COUNTIFS(Data!$C:$C,"="&B36,Data!$D:$D,"="&ServeIn) -> 0 | E36: =COUNTIFS(Data!$C:$C,"="&B36,Data!$D:$D,"="&ServeAce) -> 0 | F36: =COUNTIFS(Data!$C:$C,"="&B36,Data!$D:$D,"="&ServeError) -> 0 | G36: =SUM(D36:F36) -> 0 | H36: =IF((D36+E36+F36)=0,0,(D36+E36)/(D36+E36+F36)) -> 0 | I36: =COUNTIFS(Data!$C:$C,"="&B36,Data!$D:$D,"="&Dig) -> 0 | J36: =COUNTIFS(Data!$C:$C,"="&B36,Data!$D:$D,"="&Cover) -> 0 | K36: =J36+I36 -> 0 | L36: =COUNTIFS(Data!$C:$C,"="&B36,Data!$D:$D,"="&Pass3) -> 0 | M36: =COUNTIFS(Data!$C:$C,"="&B36,Data!$D:$D,"="&Pass2) -> 0 | N36: =COUNTIFS(Data!$C:$C,"="&B36,Data!$D:$D,"="&Pass1) -> 0 | O36: =COUNTIFS(Data!$C:$C,"="&B36,Data!$D:$D,"="&Pass0) -> 0 | P36: =L36*3+M36*2+N36*1 -> 0 | Q36: =COUNTIFS(Data!$C:$C,"="&$B36,Data!$D:$D,"="&KillAttempt) -> 0 | R36: =COUNTIFS(Data!$C:$C,"="&$B36,Data!$D:$D,"="&KillSuccess) -> 0 | S36: =COUNTIFS(Data!$C:$C,"="&$B36,Data!$D:$D,"="&KillError) -> 0 | T36: =IF((Q36+R36+S36)=0,0,(R36-S36)/(Q36+R36+S36)) -> 0 | U36: =COUNTIFS(Data!$C:$C,"="&$B36,Data!$D:$D,"="&AssistZero) -> 0 | V36: =COUNTIFS(Data!$C:$C,"="&$B36,Data!$D:$D,"="&AssistSuccess) -> 0 | W36: =COUNTIFS(Data!$C:$C,"="&$B36,Data!$D:$D,"="&AssistError) -> 0 | X36: =IF((U36+V36+W36)=0,0,(V36)/(U36+V36+W36)) -> 0 | Y36: =COUNTIFS(Data!$C:$C,"="&$B36,Data!$D:$D,"="&BlockHalf) -> 0 | Z36: =COUNTIFS(Data!$C:$C,"="&$B36,Data!$D:$D,"="&BlockSolo) -> 0 | AA36: =Y36/2+Z36 -> 0 | AB36: {=COUNTIFS(Data!$C:$C,"="&$B36,Data!$D:$D,"="&BlockKillHalf)} -> 0 | AC36: =COUNTIFS(Data!$C:$C,"="&$B36,Data!$D:$D,"="&BlockKillSolo) -> 0 | AD36: =AB36*0.5+AC36 -> 0 | AE36: =COUNTIFS(Data!$C:$C,"="&$B36,Data!$D:$D,"="&GeneralError) -> 0
B37: =Legend!A18 -> k | C37: =Legend!B18&" - "&Legend!C18 -> 12 - Kaito | D37: =COUNTIFS(Data!$C:$C,"="&B37,Data!$D:$D,"="&ServeIn) -> 0 | E37: =COUNTIFS(Data!$C:$C,"="&B37,Data!$D:$D,"="&ServeAce) -> 0 | F37: =COUNTIFS(Data!$C:$C,"="&B37,Data!$D:$D,"="&ServeError) -> 0 | G37: =SUM(D37:F37) -> 0 | H37: =IF((D37+E37+F37)=0,0,(D37+E37)/(D37+E37+F37)) -> 0 | I37: =COUNTIFS(Data!$C:$C,"="&B37,Data!$D:$D,"="&Dig) -> 0 | J37: =COUNTIFS(Data!$C:$C,"="&B37,Data!$D:$D,"="&Cover) -> 0 | K37: =J37+I37 -> 0 | L37: =COUNTIFS(Data!$C:$C,"="&B37,Data!$D:$D,"="&Pass3) -> 0 | M37: =COUNTIFS(Data!$C:$C,"="&B37,Data!$D:$D,"="&Pass2) -> 0 | N37: =COUNTIFS(Data!$C:$C,"="&B37,Data!$D:$D,"="&Pass1) -> 0 | O37: =COUNTIFS(Data!$C:$C,"="&B37,Data!$D:$D,"="&Pass0) -> 0 | P37: =L37*3+M37*2+N37*1 -> 0 | Q37: =COUNTIFS(Data!$C:$C,"="&$B37,Data!$D:$D,"="&KillAttempt) -> 0 | R37: =COUNTIFS(Data!$C:$C,"="&$B37,Data!$D:$D,"="&KillSuccess) -> 0 | S37: =COUNTIFS(Data!$C:$C,"="&$B37,Data!$D:$D,"="&KillError) -> 0 | T37: =IF((Q37+R37+S37)=0,0,(R37-S37)/(Q37+R37+S37)) -> 0 | U37: =COUNTIFS(Data!$C:$C,"="&$B37,Data!$D:$D,"="&AssistZero) -> 0 | V37: =COUNTIFS(Data!$C:$C,"="&$B37,Data!$D:$D,"="&AssistSuccess) -> 0 | W37: =COUNTIFS(Data!$C:$C,"="&$B37,Data!$D:$D,"="&AssistError) -> 0 | X37: =IF((U37+V37+W37)=0,0,(V37)/(U37+V37+W37)) -> 0 | Y37: =COUNTIFS(Data!$C:$C,"="&$B37,Data!$D:$D,"="&BlockHalf) -> 0 | Z37: =COUNTIFS(Data!$C:$C,"="&$B37,Data!$D:$D,"="&BlockSolo) -> 0 | AA37: =Y37/2+Z37 -> 0 | AB37: {=COUNTIFS(Data!$C:$C,"="&$B37,Data!$D:$D,"="&BlockKillHalf)} -> 0 | AC37: =COUNTIFS(Data!$C:$C,"="&$B37,Data!$D:$D,"="&BlockKillSolo) -> 0 | AD37: =AB37*0.5+AC37 -> 0 | AE37: =COUNTIFS(Data!$C:$C,"="&$B37,Data!$D:$D,"="&GeneralError) -> 0 | AG37: ›
B38: =Legend!A19 -> h | C38: =Legend!B19&" - "&Legend!C19 -> 13 - Hayden | D38: =COUNTIFS(Data!$C:$C,"="&B38,Data!$D:$D,"="&ServeIn) -> 0 | E38: =COUNTIFS(Data!$C:$C,"="&B38,Data!$D:$D,"="&ServeAce) -> 0 | F38: =COUNTIFS(Data!$C:$C,"="&B38,Data!$D:$D,"="&ServeError) -> 0 | G38: =SUM(D38:F38) -> 0 | H38: =IF((D38+E38+F38)=0,0,(D38+E38)/(D38+E38+F38)) -> 0 | I38: =COUNTIFS(Data!$C:$C,"="&B38,Data!$D:$D,"="&Dig) -> 0 | J38: =COUNTIFS(Data!$C:$C,"="&B38,Data!$D:$D,"="&Cover) -> 0 | K38: =J38+I38 -> 0 | L38: =COUNTIFS(Data!$C:$C,"="&B38,Data!$D:$D,"="&Pass3) -> 0 | M38: =COUNTIFS(Data!$C:$C,"="&B38,Data!$D:$D,"="&Pass2) -> 0 | N38: =COUNTIFS(Data!$C:$C,"="&B38,Data!$D:$D,"="&Pass1) -> 0 | O38: =COUNTIFS(Data!$C:$C,"="&B38,Data!$D:$D,"="&Pass0) -> 0 | P38: =L38*3+M38*2+N38*1 -> 0 | Q38: =COUNTIFS(Data!$C:$C,"="&$B38,Data!$D:$D,"="&KillAttempt) -> 0 | R38: =COUNTIFS(Data!$C:$C,"="&$B38,Data!$D:$D,"="&KillSuccess) -> 0 | S38: =COUNTIFS(Data!$C:$C,"="&$B38,Data!$D:$D,"="&KillError) -> 0 | T38: =IF((Q38+R38+S38)=0,0,(R38-S38)/(Q38+R38+S38)) -> 0 | U38: =COUNTIFS(Data!$C:$C,"="&$B38,Data!$D:$D,"="&AssistZero) -> 0 | V38: =COUNTIFS(Data!$C:$C,"="&$B38,Data!$D:$D,"="&AssistSuccess) -> 0 | W38: =COUNTIFS(Data!$C:$C,"="&$B38,Data!$D:$D,"="&AssistError) -> 0 | X38: =IF((U38+V38+W38)=0,0,(V38)/(U38+V38+W38)) -> 0 | Y38: =COUNTIFS(Data!$C:$C,"="&$B38,Data!$D:$D,"="&BlockHalf) -> 0 | Z38: =COUNTIFS(Data!$C:$C,"="&$B38,Data!$D:$D,"="&BlockSolo) -> 0 | AA38: =Y38/2+Z38 -> 0 | AB38: {=COUNTIFS(Data!$C:$C,"="&$B38,Data!$D:$D,"="&BlockKillHalf)} -> 0 | AC38: =COUNTIFS(Data!$C:$C,"="&$B38,Data!$D:$D,"="&BlockKillSolo) -> 0 | AD38: =AB38*0.5+AC38 -> 0 | AE38: =COUNTIFS(Data!$C:$C,"="&$B38,Data!$D:$D,"="&GeneralError) -> 0
B39: =Legend!A20 -> j | C39: =Legend!B20&" - "&Legend!C20 -> 23 - Jayden | D39: =COUNTIFS(Data!$C:$C,"="&B39,Data!$D:$D,"="&ServeIn) -> 0 | E39: =COUNTIFS(Data!$C:$C,"="&B39,Data!$D:$D,"="&ServeAce) -> 0 | F39: =COUNTIFS(Data!$C:$C,"="&B39,Data!$D:$D,"="&ServeError) -> 0 | G39: =SUM(D39:F39) -> 0 | H39: =IF((D39+E39+F39)=0,0,(D39+E39)/(D39+E39+F39)) -> 0 | I39: =COUNTIFS(Data!$C:$C,"="&B39,Data!$D:$D,"="&Dig) -> 0 | J39: =COUNTIFS(Data!$C:$C,"="&B39,Data!$D:$D,"="&Cover) -> 0 | K39: =J39+I39 -> 0 | L39: =COUNTIFS(Data!$C:$C,"="&B39,Data!$D:$D,"="&Pass3) -> 0 | M39: =COUNTIFS(Data!$C:$C,"="&B39,Data!$D:$D,"="&Pass2) -> 0 | N39: =COUNTIFS(Data!$C:$C,"="&B39,Data!$D:$D,"="&Pass1) -> 0 | O39: =COUNTIFS(Data!$C:$C,"="&B39,Data!$D:$D,"="&Pass0) -> 0 | P39: =L39*3+M39*2+N39*1 -> 0 | Q39: =COUNTIFS(Data!$C:$C,"="&$B39,Data!$D:$D,"="&KillAttempt) -> 0 | R39: =COUNTIFS(Data!$C:$C,"="&$B39,Data!$D:$D,"="&KillSuccess) -> 0 | S39: =COUNTIFS(Data!$C:$C,"="&$B39,Data!$D:$D,"="&KillError) -> 0 | T39: =IF((Q39+R39+S39)=0,0,(R39-S39)/(Q39+R39+S39)) -> 0 | U39: =COUNTIFS(Data!$C:$C,"="&$B39,Data!$D:$D,"="&AssistZero) -> 0 | V39: =COUNTIFS(Data!$C:$C,"="&$B39,Data!$D:$D,"="&AssistSuccess) -> 0 | W39: =COUNTIFS(Data!$C:$C,"="&$B39,Data!$D:$D,"="&AssistError) -> 0 | X39: =IF((U39+V39+W39)=0,0,(V39)/(U39+V39+W39)) -> 0 | Y39: =COUNTIFS(Data!$C:$C,"="&$B39,Data!$D:$D,"="&BlockHalf) -> 0 | Z39: =COUNTIFS(Data!$C:$C,"="&$B39,Data!$D:$D,"="&BlockSolo) -> 0 | AA39: =Y39/2+Z39 -> 0 | AB39: {=COUNTIFS(Data!$C:$C,"="&$B39,Data!$D:$D,"="&BlockKillHalf)} -> 0 | AC39: =COUNTIFS(Data!$C:$C,"="&$B39,Data!$D:$D,"="&BlockKillSolo) -> 0 | AD39: =AB39*0.5+AC39 -> 0 | AE39: =COUNTIFS(Data!$C:$C,"="&$B39,Data!$D:$D,"="&GeneralError) -> 0
B40: =Legend!A25 -> tt | C40: =Legend!C25 -> Team | AE40: =COUNTIFS(Data!$C:$C,"="&$B40,Data!$D:$D,"="&GeneralError) -> 0
D42: Dig: defensive bump that keeps the ball from hitting the floor when it's sent to your side of the court with an offensive attack, usually a spike. | L42: 0 : pass directly resulted in an error | Q42: Hit Eff = | R42: Kills - Errors | U42: Attempt: not result in a kill | Y42: B: Block (opposition covered, ball still in play)
L43: 1 : poor (setter only one option or not to setter) | R43: Attacks + Kills + Errors | U43: Assist: resulted in a kill | Y43: BK: Block Kill (point)
D44: Cover: save from a block | L44: 2 : good (setter has primarily two options) | U44: Error: usually ball handling error (double hit, thrown ball, lifted ball) | Y44: Half : 2 or more players in wall even if only one player touched the ball
L45: 3 : perfect (giving setter all setting options)
U46: Set Eff = | V46: Assists
...

Sheet Set Score
C1: Score Calcs | D1: Data
C2: SX Srv Aces | D2: =COUNTIFS(Data!$A:$A,"="&$D$18,Data!$C:$C,"<>"&OppKey,Data!$D:$D,"="&ServeAce) -> 0
C3: SX Srv Errors | D3: =COUNTIFS(Data!$A:$A,"="&$D$18,Data!$C:$C,"<>"&OppKey,Data!$D:$D,"="&ServeError) -> 0
C4: SX Pass Errors | D4: =COUNTIFS(Data!$A:$A,"="&$D$18,Data!$C:$C,"<>"&OppKey,Data!$D:$D,"="&Pass0) -> 0
C5: SX Kills | D5: =COUNTIFS(Data!$A:$A,"="&$D$18,Data!$C:$C,"<>"&OppKey,Data!$D:$D,"="&KillSuccess) -> 0
C6: SX Kill Err | D6: =COUNTIFS(Data!$A:$A,"="&$D$18,Data!$C:$C,"<>"&OppKey,Data!$D:$D,"="&KillError) -> 0
C7: SX Set Err | D7: =COUNTIFS(Data!$A:$A,"="&$D$18,Data!$C:$C,"<>"&OppKey,Data!$D:$D,"="&AssistError) -> 0
C8: SX Block Half | D8: {=COUNTIFS(Data!$A:$A,"="&$D$18,Data!$C:$C,"<>"&OppKey,Data!$D:$D,"="&BlockKillHalf)} -> 0
C9: SX Block Solo | D9: =COUNTIFS(Data!$A:$A,"="&$D$18,Data!$C:$C,"<>"&OppKey,Data!$D:$D,"="&BlockKillSolo) -> 0
C10: SX BHA Err | D10: =COUNTIFS(Data!$A:$A,"="&$D$18,Data!$C:$C,"<>"&OppKey,Data!$D:$D,"="&GeneralError) -> 0
C12: Opp Aces | D12: =COUNTIFS(Data!$A:$A,"="&$D$18,Data!$C:$C,"="&OppKey,Data!$D:$D,"="&ServeAce) -> 0
C13: Opp Srv Errors | D13: =COUNTIFS(Data!$A:$A,"="&$D$18,Data!$C:$C,"="&OppKey,Data!$D:$D,"="&ServeError) -> 0
C14: Opp Kills | D14: =COUNTIFS(Data!$A:$A,"="&$D$18,Data!$C:$C,"="&OppKey,Data!$D:$D,"="&KillSuccess) -> 0
C15: Opp Kill Err | D15: =COUNTIFS(Data!$A:$A,"="&$D$18,Data!$C:$C,"="&OppKey,Data!$D:$D,"="&KillError) -> 0
C16: Opp BHA Err | D16: =COUNTIFS(Data!$A:$A,"="&$D$18,Data!$C:$C,"="&OppKey,Data!$D:$D,"="&GeneralError) -> 0
C18: Set | D18: 5
C19: Team 1 | D19: =D2+D5+D8/2+D9+D13+D15+D16 -> 0
C20: Team 2 | D20: =D3+D4+D6+D7+D10+D12+D14 -> 0
C22: Team Stats | D22: Serving | I22: Defence | L22: Passing | Q22: Kills | U22: Set Assists | Y22: Blocks | AE22: Other
B23: Name Key | D23: In | E23: Aces | F23: Errors | G23: Total | H23: % | I23: Digs | J23: Covers | K23: Total | L23: 3 | M23: 2 | N23: 1 | O23: 0 | P23: Score | Q23: Attacks | R23: Kills | S23: Errors | T23: Hit Eff. | U23: Attempt | V23: Assists | W23: Errors | X23: Set Eff. | Y23: B Half | Z23: B Solo | AA23: B Score | AB23: BK Half | AC23: BK Solo | AD23: BK Score | AE23: Errors
C24: Team Total | D24: =SUM(D30:D40) -> 0 | E24: =SUM(E30:E40) -> 0 | F24: =SUM(F30:F40) -> 0 | G24: =SUM(D24:F24) -> 0 | H24: =IF((F24+E24+D24)=0,0,(D24+E24)/(F24+E24+D24)) -> 0 | I24: =SUM(I30:I40) -> 0 | J24: =SUM(J30:J40) -> 0 | K24: =SUM(K30:K40) -> 0 | L24: =SUM(L30:L40) -> 0 | M24: =SUM(M30:M40) -> 0 | N24: =SUM(N30:N40) -> 0 | O24: =SUM(O30:O40) -> 0 | P24: =SUM(P30:P40) -> 0 | ... S24: =SUM(S30:S40) -> 0 | T24: =IF((Q24+R24+S24)=0,0,(R24-S24)/(Q24+R24+S24)) -> 0 | U24: =SUM(U30:U40) -> 0 | V24: =SUM(V30:V40) -> 0 | W24: =SUM(W30:W40) -> 0 | X24: =IF((U24+V24+W24)=0,0,(V24)/(U24+V24+W24)) -> 0 | Y24: =SUM(Y30:Y39) -> 0 | Z24: =SUM(Z30:Z39) -> 0 | AA24: =SUM(AA30:AA39) -> 0 | AB24: =SUM(AB30:AB39) -> 0 | AC24: =SUM(AC30:AC39) -> 0 | AD24: =SUM(AD30:AD39) -> 0 | AE24: =SUM(AE30:AE40) -> 0
C25: % split per skill | D25: =IF(G24=0,0,D24/G24) -> 0 | E25: =IF(G24=0,0,E24/G24) -> 0 | F25: =IF(G24=0,0,F24/G24) -> 0 | L25: =L24/(L24+M24+N24+O24) -> #DIV/0! | M25: =M24/(L24+M24+N24+O24) -> #DIV/0! | N25: =N24/(L24+M24+N24+O24) -> #DIV/0! | O25: =O24/(L24+M24+N24+O24) -> #DIV/0! | Q25: =Q24/(Q24+R24+S24) -> #DIV/0! | R25: =R24/(Q24+R24+S24) -> #DIV/0! | S25: =S24/(S24+R24+Q24) -> #DIV/0! | U25: =U24/(U24+V24+W24) -> #DIV/0! | V25: =V24/(U24+V24+W24) -> #DIV/0! | W25: =W24/(U24+V24+W24) -> #DIV/0!
B26: =Legend!A26 -> p | C26: Opposition | D26: =COUNTIFS(Data!$A:$A,"="&$D$18,Data!$C:$C,"="&B26,Data!$D:$D,"="&ServeIn) -> 0 | E26: =COUNTIFS(Data!$A:$A,"="&$D$18,Data!$C:$C,"="&B26,Data!$D:$D,"="&ServeAce) -> 0 | F26: =COUNTIFS(Data!$A:$A,"="&$D$18,Data!$C:$C,"="&B26,Data!$D:$D,"="&ServeError) -> 0 | G26: =SUM(D26:F26) -> 0 | H26: =IF((F26+E26+D26)=0,0,(D26+E26)/(F26+E26+D26)) -> 0 | Q26: =COUNTIFS(Data!$A:$A,"="&$D$18,Data!$C:$C,"="&B26,Data!$D:$D,"="&KillAttempt) -> 0 | R26: =COUNTIFS(Data!$A:$A,"="&$D$18,Data!$C:$C,"="&B26,Data!$D:$D,"="&KillSuccess) -> 0 | S26: =COUNTIFS(Data!$A:$A,"="&$D$18,Data!$C:$C,"="&B26,Data!$D:$D,"="&KillError) -> 0 | AE26: =COUNTIFS(Data!$A:$A,"="&$D$18,Data!$C:$C,"="&$B26,Data!$D:$D,"="&GeneralError) -> 0
C28: Player Stats | D28: Serving | I28: Defence | L28: Passing | Q28: Kills | U28: Set Assists | Y28: Blocks | AE28: Other
B29: Name Key | D29: In | E29: Aces | F29: Errors | G29: Total | H29: % | I29: Digs | J29: Covers | K29: Total | L29: 3 | M29: 2 | N29: 1 | O29: 0 | P29: Score | Q29: Attacks | R29: Kills | S29: Errors | T29: Hit Eff. | U29: Attempt | V29: Assists | W29: Errors | X29: Set Eff. | Y29: B Half | Z29: B Solo | AA29: B Score | AB29: BK Half | AC29: BK Solo | AD29: BK Score | AE29: Errors
B30: =Legend!A11 -> s | C30: =Legend!B11&" - "&Legend!C11 -> 1 - Sam | D30: =COUNTIFS(Data!$A:$A,"="&$D$18,Data!$C:$C,"="&B30,Data!$D:$D,"="&ServeIn) -> 0 | E30: =COUNTIFS(Data!$A:$A,"="&$D$18,Data!$C:$C,"="&B30,Data!$D:$D,"="&ServeAce) -> 0 | F30: =COUNTIFS(Data!$A:$A,"="&$D$18,Data!$C:$C,"="&B30,Data!$D:$D,"="&ServeError) -> 0 | G30: =SUM(D30:F30) -> 0 | H30: =IF((D30+E30+F30)=0,0,(D30+E30)/(D30+E30+F30)) -> 0 | I30: =COUNTIFS(Data!$A:$A,"="&$D$18,Data!$C:$C,"="&B30,Data!$D:$D,"="&Dig) -> 0 | J30: =COUNTIFS(Data!$A:$A,"="&$D$18,Data!$C:$C,"="&B30,Data!$D:$D,"="&Cover) -> 0 | K30: =J30+I30 -> 0 | L30: =COUNTIFS(Data!$A:$A,"="&$D$18,Data!$C:$C,"="&B30,Data!$D:$D,"="&Pass3) -> 0 | M30: =COUNTIFS(Data!$A:$A,"="&$D$18,Data!$C:$C,"="&B30,Data!$D:$D,"="&Pass2) -> 0 | N30: =COUNTIFS(Data!$A:$A,"="&$D$18,Data!$C:$C,"="&B30,Data!$D:$D,"="&Pass1) -> 0 | O30: =COUNTIFS(Data!$A:$A,"="&$D$18,Data!$C:$C,"="&B30,Data!$D:$D,"="&Pass0) -> 0 | P30: =L30*3+M30*2+N30*1 -> 0 | Q30: =COUNTIFS(Data!$A:$A,"="&$D$18,Data!$C:$C,"="&$B30,Data!$D:$D,"="&KillAttempt) -> 0 | R30: =COUNTIFS(Data!$A:$A,"="&$D$18,Data!$C:$C,"="&$B30,Data!$D:$D,"="&KillSuccess) -> 0 | S30: =COUNTIFS(Data!$A:$A,"="&$D$18,Data!$C:$C,"="&$B30,Data!$D:$D,"="&KillError) -> 0 | T30: =IF((Q30+R30+S30)=0,0,(R30-S30)/(Q30+R30+S30)) -> 0 | U30: =COUNTIFS(Data!$A:$A,"="&$D$18,Data!$C:$C,"="&$B30,Data!$D:$D,"="&AssistZero) -> 0 | V30: =COUNTIFS(Data!$A:$A,"="&$D$18,Data!$C:$C,"="&$B30,Data!$D:$D,"="&AssistSuccess) -> 0 | W30: =COUNTIFS(Data!$A:$A,"="&$D$18,Data!$C:$C,"="&$B30,Data!$D:$D,"="&AssistError) -> 0 | X30: =IF((U30+V30+W30)=0,0,(V30)/(U30+V30+W30)) -> 0 | Y30: =COUNTIFS(Data!$A:$A,"="&$D$18,Data!$C:$C,"="&$B30,Data!$D:$D,"="&BlockHalf) -> 0 | Z30: =COUNTIFS(Data!$A:$A,"="&$D$18,Data!$C:$C,"="&$B30,Data!$D:$D,"="&BlockSolo) -> 0 | AA30: =Y30*0.5+Z30 -> 0 | AB30: {=COUNTIFS(Data!$A:$A,"="&$D$18,Data!$C:$C,"="&$B30,Data!$D:$D,"="&BlockKillHalf)} -> 0 | AC30: =COUNTIFS(Data!$A:$A,"="&$D$18,Data!$C:$C,"="&$B30,Data!$D:$D,"="&BlockKillSolo) -> 0 | AD30: =AB30*0.5+AC30 -> 0 | AE30: =COUNTIFS(Data!$A:$A,"="&$D$18,Data!$C:$C,"="&$B30,Data!$D:$D,"="&GeneralError) -> 0
B31: =Legend!A12 -> r | C31: =Legend!B12&" - "&Legend!C12 -> 2 - Reece | D31: =COUNTIFS(Data!$A:$A,"="&$D$18,Data!$C:$C,"="&B31,Data!$D:$D,"="&ServeIn) -> 0 | E31: =COUNTIFS(Data!$A:$A,"="&$D$18,Data!$C:$C,"="&B31,Data!$D:$D,"="&ServeAce) -> 0 | F31: =COUNTIFS(Data!$A:$A,"="&$D$18,Data!$C:$C,"="&B31,Data!$D:$D,"="&ServeError) -> 0 | G31: =SUM(D31:F31) -> 0 | H31: =IF((D31+E31+F31)=0,0,(D31+E31)/(D31+E31+F31)) -> 0 | I31: =COUNTIFS(Data!$A:$A,"="&$D$18,Data!$C:$C,"="&B31,Data!$D:$D,"="&Dig) -> 0 | J31: =COUNTIFS(Data!$A:$A,"="&$D$18,Data!$C:$C,"="&B31,Data!$D:$D,"="&Cover) -> 0 | K31: =J31+I31 -> 0 | L31: =COUNTIFS(Data!$A:$A,"="&$D$18,Data!$C:$C,"="&B31,Data!$D:$D,"="&Pass3) -> 0 | M31: =COUNTIFS(Data!$A:$A,"="&$D$18,Data!$C:$C,"="&B31,Data!$D:$D,"="&Pass2) -> 0 | N31: =COUNTIFS(Data!$A:$A,"="&$D$18,Data!$C:$C,"="&B31,Data!$D:$D,"="&Pass1) -> 0 | O31: =COUNTIFS(Data!$A:$A,"="&$D$18,Data!$C:$C,"="&B31,Data!$D:$D,"="&Pass0) -> 0 | P31: =L31*3+M31*2+N31*1 -> 0 | Q31: =COUNTIFS(Data!$A:$A,"="&$D$18,Data!$C:$C,"="&$B31,Data!$D:$D,"="&KillAttempt) -> 0 | R31: =COUNTIFS(Data!$A:$A,"="&$D$18,Data!$C:$C,"="&$B31,Data!$D:$D,"="&KillSuccess) -> 0 | S31: =COUNTIFS(Data!$A:$A,"="&$D$18,Data!$C:$C,"="&$B31,Data!$D:$D,"="&KillError) -> 0 | T31: =IF((Q31+R31+S31)=0,0,(R31-S31)/(Q31+R31+S31)) -> 0 | U31: =COUNTIFS(Data!$A:$A,"="&$D$18,Data!$C:$C,"="&$B31,Data!$D:$D,"="&AssistZero) -> 0 | V31: =COUNTIFS(Data!$A:$A,"="&$D$18,Data!$C:$C,"="&$B31,Data!$D:$D,"="&AssistSuccess) -> 0 | W31: =COUNTIFS(Data!$A:$A,"="&$D$18,Data!$C:$C,"="&$B31,Data!$D:$D,"="&AssistError) -> 0 | X31: =IF((U31+V31+W31)=0,0,(V31)/(U31+V31+W31)) -> 0 | Y31: =COUNTIFS(Data!$A:$A,"="&$D$18,Data!$C:$C,"="&$B31,Data!$D:$D,"="&BlockHalf) -> 0 | Z31: =COUNTIFS(Data!$A:$A,"="&$D$18,Data!$C:$C,"="&$B31,Data!$D:$D,"="&BlockSolo) -> 0 | AA31: =Y31*0.5+Z31 -> 0 | AB31: {=COUNTIFS(Data!$A:$A,"="&$D$18,Data!$C:$C,"="&$B31,Data!$D:$D,"="&BlockKillHalf)} -> 0 | AC31: =COUNTIFS(Data!$A:$A,"="&$D$18,Data!$C:$C,"="&$B31,Data!$D:$D,"="&BlockKillSolo) -> 0 | AD31: =AB31*0.5+AC31 -> 0 | AE31: =COUNTIFS(Data!$A:$A,"="&$D$18,Data!$C:$C,"="&$B31,Data!$D:$D,"="&GeneralError) -> 0
B32: =Legend!A13 -> c | C32: =Legend!B13&" - "&Legend!C13 -> 3 - Cameron | D32: =COUNTIFS(Data!$A:$A,"="&$D$18,Data!$C:$C,"="&B32,Data!$D:$D,"="&ServeIn) -> 0 | E32: =COUNTIFS(Data!$A:$A,"="&$D$18,Data!$C:$C,"="&B32,Data!$D:$D,"="&ServeAce) -> 0 | F32: =COUNTIFS(Data!$A:$A,"="&$D$18,Data!$C:$C,"="&B32,Data!$D:$D,"="&ServeError) -> 0 | G32: =SUM(D32:F32) -> 0 | H32: =IF((D32+E32+F32)=0,0,(D32+E32)/(D32+E32+F32)) -> 0 | I32: =COUNTIFS(Data!$A:$A,"="&$D$18,Data!$C:$C,"="&B32,Data!$D:$D,"="&Dig) -> 0 | J32: =COUNTIFS(Data!$A:$A,"="&$D$18,Data!$C:$C,"="&B32,Data!$D:$D,"="&Cover) -> 0 | K32: =J32+I32 -> 0 | L32: =COUNTIFS(Data!$A:$A,"="&$D$18,Data!$C:$C,"="&B32,Data!$D:$D,"="&Pass3) -> 0 | M32: =COUNTIFS(Data!$A:$A,"="&$D$18,Data!$C:$C,"="&B32,Data!$D:$D,"="&Pass2) -> 0 | N32: =COUNTIFS(Data!$A:$A,"="&$D$18,Data!$C:$C,"="&B32,Data!$D:$D,"="&Pass1) -> 0 | O32: =COUNTIFS(Data!$A:$A,"="&$D$18,Data!$C:$C,"="&B32,Data!$D:$D,"="&Pass0) -> 0 | P32: =L32*3+M32*2+N32*1 -> 0 | Q32: =COUNTIFS(Data!$A:$A,"="&$D$18,Data!$C:$C,"="&$B32,Data!$D:$D,"="&KillAttempt) -> 0 | R32: =COUNTIFS(Data!$A:$A,"="&$D$18,Data!$C:$C,"="&$B32,Data!$D:$D,"="&KillSuccess) -> 0 | S32: =COUNTIFS(Data!$A:$A,"="&$D$18,Data!$C:$C,"="&$B32,Data!$D:$D,"="&KillError) -> 0 | T32: =IF((Q32+R32+S32)=0,0,(R32-S32)/(Q32+R32+S32)) -> 0 | U32: =COUNTIFS(Data!$A:$A,"="&$D$18,Data!$C:$C,"="&$B32,Data!$D:$D,"="&AssistZero) -> 0 | V32: =COUNTIFS(Data!$A:$A,"="&$D$18,Data!$C:$C,"="&$B32,Data!$D:$D,"="&AssistSuccess) -> 0 | W32: =COUNTIFS(Data!$A:$A,"="&$D$18,Data!$C:$C,"="&$B32,Data!$D:$D,"="&AssistError) -> 0 | X32: =IF((U32+V32+W32)=0,0,(V32)/(U32+V32+W32)) -> 0 | Y32: =COUNTIFS(Data!$A:$A,"="&$D$18,Data!$C:$C,"="&$B32,Data!$D:$D,"="&BlockHalf) -> 0 | Z32: =COUNTIFS(Data!$A:$A,"="&$D$18,Data!$C:$C,"="&$B32,Data!$D:$D,"="&BlockSolo) -> 0 | AA32: =Y32*0.5+Z32 -> 0 | AB32: {=COUNTIFS(Data!$A:$A,"="&$D$18,Data!$C:$C,"="&$B32,Data!$D:$D,"="&BlockKillHalf)} -> 0 | AC32: =COUNTIFS(Data!$A:$A,"="&$D$18,Data!$C:$C,"="&$B32,Data!$D:$D,"="&BlockKillSolo) -> 0 | AD32: =AB32*0.5+AC32 -> 0 | AE32: =COUNTIFS(Data!$A:$A,"="&$D$18,Data!$C:$C,"="&$B32,Data!$D:$D,"="&GeneralError) -> 0
B33: =Legend!A14 -> l | C33: =Legend!B14&" - "&Legend!C14 -> 5 - Levi | D33: =COUNTIFS(Data!$A:$A,"="&$D$18,Data!$C:$C,"="&B33,Data!$D:$D,"="&ServeIn) -> 0 | E33: =COUNTIFS(Data!$A:$A,"="&$D$18,Data!$C:$C,"="&B33,Data!$D:$D,"="&ServeAce) -> 0 | F33: =COUNTIFS(Data!$A:$A,"="&$D$18,Data!$C:$C,"="&B33,Data!$D:$D,"="&ServeError) -> 0 | G33: =SUM(D33:F33) -> 0 | H33: =IF((D33+E33+F33)=0,0,(D33+E33)/(D33+E33+F33)) -> 0 | I33: =COUNTIFS(Data!$A:$A,"="&$D$18,Data!$C:$C,"="&B33,Data!$D:$D,"="&Dig) -> 0 | J33: =COUNTIFS(Data!$A:$A,"="&$D$18,Data!$C:$C,"="&B33,Data!$D:$D,"="&Cover) -> 0 | K33: =J33+I33 -> 0 | L33: =COUNTIFS(Data!$A:$A,"="&$D$18,Data!$C:$C,"="&B33,Data!$D:$D,"="&Pass3) -> 0 | M33: =COUNTIFS(Data!$A:$A,"="&$D$18,Data!$C:$C,"="&B33,Data!$D:$D,"="&Pass2) -> 0 | N33: =COUNTIFS(Data!$A:$A,"="&$D$18,Data!$C:$C,"="&B33,Data!$D:$D,"="&Pass1) -> 0 | O33: =COUNTIFS(Data!$A:$A,"="&$D$18,Data!$C:$C,"="&B33,Data!$D:$D,"="&Pass0) -> 0 | P33: =L33*3+M33*2+N33*1 -> 0 | Q33: =COUNTIFS(Data!$A:$A,"="&$D$18,Data!$C:$C,"="&$B33,Data!$D:$D,"="&KillAttempt) -> 0 | R33: =COUNTIFS(Data!$A:$A,"="&$D$18,Data!$C:$C,"="&$B33,Data!$D:$D,"="&KillSuccess) -> 0 | S33: =COUNTIFS(Data!$A:$A,"="&$D$18,Data!$C:$C,"="&$B33,Data!$D:$D,"="&KillError) -> 0 | T33: =IF((Q33+R33+S33)=0,0,(R33-S33)/(Q33+R33+S33)) -> 0 | U33: =COUNTIFS(Data!$A:$A,"="&$D$18,Data!$C:$C,"="&$B33,Data!$D:$D,"="&AssistZero) -> 0 | V33: =COUNTIFS(Data!$A:$A,"="&$D$18,Data!$C:$C,"="&$B33,Data!$D:$D,"="&AssistSuccess) -> 0 | W33: =COUNTIFS(Data!$A:$A,"="&$D$18,Data!$C:$C,"="&$B33,Data!$D:$D,"="&AssistError) -> 0 | X33: =IF((U33+V33+W33)=0,0,(V33)/(U33+V33+W33)) -> 0 | Y33: =COUNTIFS(Data!$A:$A,"="&$D$18,Data!$C:$C,"="&$B33,Data!$D:$D,"="&BlockHalf) -> 0 | Z33: =COUNTIFS(Data!$A:$A,"="&$D$18,Data!$C:$C,"="&$B33,Data!$D:$D,"="&BlockSolo) -> 0 | AA33: =Y33*0.5+Z33 -> 0 | AB33: {=COUNTIFS(Data!$A:$A,"="&$D$18,Data!$C:$C,"="&$B33,Data!$D:$D,"="&BlockKillHalf)} -> 0 | AC33: =COUNTIFS(Data!$A:$A,"="&$D$18,Data!$C:$C,"="&$B33,Data!$D:$D,"="&BlockKillSolo) -> 0 | AD33: =AB33*0.5+AC33 -> 0 | AE33: =COUNTIFS(Data!$A:$A,"="&$D$18,Data!$C:$C,"="&$B33,Data!$D:$D,"="&GeneralError) -> 0
B34: =Legend!A15 -> t | C34: =Legend!B15&" - "&Legend!C15 -> 6 - Tom | D34: =COUNTIFS(Data!$A:$A,"="&$D$18,Data!$C:$C,"="&B34,Data!$D:$D,"="&ServeIn) -> 0 | E34: =COUNTIFS(Data!$A:$A,"="&$D$18,Data!$C:$C,"="&B34,Data!$D:$D,"="&ServeAce) -> 0 | F34: =COUNTIFS(Data!$A:$A,"="&$D$18,Data!$C:$C,"="&B34,Data!$D:$D,"="&ServeError) -> 0 | G34: =SUM(D34:F34) -> 0 | H34: =IF((D34+E34+F34)=0,0,(D34+E34)/(D34+E34+F34)) -> 0 | I34: =COUNTIFS(Data!$A:$A,"="&$D$18,Data!$C:$C,"="&B34,Data!$D:$D,"="&Dig) -> 0 | J34: =COUNTIFS(Data!$A:$A,"="&$D$18,Data!$C:$C,"="&B34,Data!$D:$D,"="&Cover) -> 0 | K34: =J34+I34 -> 0 | L34: =COUNTIFS(Data!$A:$A,"="&$D$18,Data!$C:$C,"="&B34,Data!$D:$D,"="&Pass3) -> 0 | M34: =COUNTIFS(Data!$A:$A,"="&$D$18,Data!$C:$C,"="&B34,Data!$D:$D,"="&Pass2) -> 0 | N34: =COUNTIFS(Data!$A:$A,"="&$D$18,Data!$C:$C,"="&B34,Data!$D:$D,"="&Pass1) -> 0 | O34: =COUNTIFS(Data!$A:$A,"="&$D$18,Data!$C:$C,"="&B34,Data!$D:$D,"="&Pass0) -> 0 | P34: =L34*3+M34*2+N34*1 -> 0 | Q34: =COUNTIFS(Data!$A:$A,"="&$D$18,Data!$C:$C,"="&$B34,Data!$D:$D,"="&KillAttempt) -> 0 | R34: =COUNTIFS(Data!$A:$A,"="&$D$18,Data!$C:$C,"="&$B34,Data!$D:$D,"="&KillSuccess) -> 0 | S34: =COUNTIFS(Data!$A:$A,"="&$D$18,Data!$C:$C,"="&$B34,Data!$D:$D,"="&KillError) -> 0 | T34: =IF((Q34+R34+S34)=0,0,(R34-S34)/(Q34+R34+S34)) -> 0 | U34: =COUNTIFS(Data!$A:$A,"="&$D$18,Data!$C:$C,"="&$B34,Data!$D:$D,"="&AssistZero) -> 0 | V34: =COUNTIFS(Data!$A:$A,"="&$D$18,Data!$C:$C,"="&$B34,Data!$D:$D,"="&AssistSuccess) -> 0 | W34: =COUNTIFS(Data!$A:$A,"="&$D$18,Data!$C:$C,"="&$B34,Data!$D:$D,"="&AssistError) -> 0 | X34: =IF((U34+V34+W34)=0,0,(V34)/(U34+V34+W34)) -> 0 | Y34: =COUNTIFS(Data!$A:$A,"="&$D$18,Data!$C:$C,"="&$B34,Data!$D:$D,"="&BlockHalf) -> 0 | Z34: =COUNTIFS(Data!$A:$A,"="&$D$18,Data!$C:$C,"="&$B34,Data!$D:$D,"="&BlockSolo) -> 0 | AA34: =Y34*0.5+Z34 -> 0 | AB34: {=COUNTIFS(Data!$A:$A,"="&$D$18,Data!$C:$C,"="&$B34,Data!$D:$D,"="&BlockKillHalf)} -> 0 | AC34: =COUNTIFS(Data!$A:$A,"="&$D$18,Data!$C:$C,"="&$B34,Data!$D:$D,"="&BlockKillSolo) -> 0 | AD34: =AB34*0.5+AC34 -> 0 | AE34: =COUNTIFS(Data!$A:$A,"="&$D$18,Data!$C:$C,"="&$B34,Data!$D:$D,"="&GeneralError) -> 0
B35: =Legend!A16 -> z | C35: =Legend!B16&" - "&Legend!C16 -> 7 - Zach | D35: =COUNTIFS(Data!$A:$A,"="&$D$18,Data!$C:$C,"="&B35,Data!$D:$D,"="&ServeIn) -> 0 | E35: =COUNTIFS(Data!$A:$A,"="&$D$18,Data!$C:$C,"="&B35,Data!$D:$D,"="&ServeAce) -> 0 | F35: =COUNTIFS(Data!$A:$A,"="&$D$18,Data!$C:$C,"="&B35,Data!$D:$D,"="&ServeError) -> 0 | G35: =SUM(D35:F35) -> 0 | H35: =IF((D35+E35+F35)=0,0,(D35+E35)/(D35+E35+F35)) -> 0 | I35: =COUNTIFS(Data!$A:$A,"="&$D$18,Data!$C:$C,"="&B35,Data!$D:$D,"="&Dig) -> 0 | J35: =COUNTIFS(Data!$A:$A,"="&$D$18,Data!$C:$C,"="&B35,Data!$D:$D,"="&Cover) -> 0 | K35: =J35+I35 -> 0 | L35: =COUNTIFS(Data!$A:$A,"="&$D$18,Data!$C:$C,"="&B35,Data!$D:$D,"="&Pass3) -> 0 | M35: =COUNTIFS(Data!$A:$A,"="&$D$18,Data!$C:$C,"="&B35,Data!$D:$D,"="&Pass2) -> 0 | N35: =COUNTIFS(Data!$A:$A,"="&$D$18,Data!$C:$C,"="&B35,Data!$D:$D,"="&Pass1) -> 0 | O35: =COUNTIFS(Data!$A:$A,"="&$D$18,Data!$C:$C,"="&B35,Data!$D:$D,"="&Pass0) -> 0 | P35: =L35*3+M35*2+N35*1 -> 0 | Q35: =COUNTIFS(Data!$A:$A,"="&$D$18,Data!$C:$C,"="&$B35,Data!$D:$D,"="&KillAttempt) -> 0 | R35: =COUNTIFS(Data!$A:$A,"="&$D$18,Data!$C:$C,"="&$B35,Data!$D:$D,"="&KillSuccess) -> 0 | S35: =COUNTIFS(Data!$A:$A,"="&$D$18,Data!$C:$C,"="&$B35,Data!$D:$D,"="&KillError) -> 0 | T35: =IF((Q35+R35+S35)=0,0,(R35-S35)/(Q35+R35+S35)) -> 0 | U35: =COUNTIFS(Data!$A:$A,"="&$D$18,Data!$C:$C,"="&$B35,Data!$D:$D,"="&AssistZero) -> 0 | V35: =COUNTIFS(Data!$A:$A,"="&$D$18,Data!$C:$C,"="&$B35,Data!$D:$D,"="&AssistSuccess) -> 0 | W35: =COUNTIFS(Data!$A:$A,"="&$D$18,Data!$C:$C,"="&$B35,Data!$D:$D,"="&AssistError) -> 0 | X35: =IF((U35+V35+W35)=0,0,(V35)/(U35+V35+W35)) -> 0 | Y35: =COUNTIFS(Data!$A:$A,"="&$D$18,Data!$C:$C,"="&$B35,Data!$D:$D,"="&BlockHalf) -> 0 | Z35: =COUNTIFS(Data!$A:$A,"="&$D$18,Data!$C:$C,"="&$B35,Data!$D:$D,"="&BlockSolo) -> 0 | AA35: =Y35*0.5+Z35 -> 0 | AB35: {=COUNTIFS(Data!$A:$A,"="&$D$18,Data!$C:$C,"="&$B35,Data!$D:$D,"="&BlockKillHalf)} -> 0 | AC35: =COUNTIFS(Data!$A:$A,"="&$D$18,Data!$C:$C,"="&$B35,Data!$D:$D,"="&BlockKillSolo) -> 0 | AD35: =AB35*0.5+AC35 -> 0 | AE35: =COUNTIFS(Data!$A:$A,"="&$D$18,Data!$C:$C,"="&$B35,Data!$D:$D,"="&GeneralError) -> 0
B36: =Legend!A17 -> b | C36: =Legend!B17&" - "&Legend!C17 -> 11 - Bodhi | D36: =COUNTIFS(Data!$A:$A,"="&$D$18,Data!$C:$C,"="&B36,Data!$D:$D,"="&ServeIn) -> 0 | E36: =COUNTIFS(Data!$A:$A,"="&$D$18,Data!$C:$C,"="&B36,Data!$D:$D,"="&ServeAce) -> 0 | F36: =COUNTIFS(Data!$A:$A,"="&$D$18,Data!$C:$C,"="&B36,Data!$D:$D,"="&ServeError) -> 0 | G36: =SUM(D36:F36) -> 0 | H36: =IF((D36+E36+F36)=0,0,(D36+E36)/(D36+E36+F36)) -> 0 | I36: =COUNTIFS(Data!$A:$A,"="&$D$18,Data!$C:$C,"="&B36,Data!$D:$D,"="&Dig) -> 0 | J36: =COUNTIFS(Data!$A:$A,"="&$D$18,Data!$C:$C,"="&B36,Data!$D:$D,"="&Cover) -> 0 | K36: =J36+I36 -> 0 | L36: =COUNTIFS(Data!$A:$A,"="&$D$18,Data!$C:$C,"="&B36,Data!$D:$D,"="&Pass3) -> 0 | M36: =COUNTIFS(Data!$A:$A,"="&$D$18,Data!$C:$C,"="&B36,Data!$D:$D,"="&Pass2) -> 0 | N36: =COUNTIFS(Data!$A:$A,"="&$D$18,Data!$C:$C,"="&B36,Data!$D:$D,"="&Pass1) -> 0 | O36: =COUNTIFS(Data!$A:$A,"="&$D$18,Data!$C:$C,"="&B36,Data!$D:$D,"="&Pass0) -> 0 | P36: =L36*3+M36*2+N36*1 -> 0 | Q36: =COUNTIFS(Data!$A:$A,"="&$D$18,Data!$C:$C,"="&$B36,Data!$D:$D,"="&KillAttempt) -> 0 | R36: =COUNTIFS(Data!$A:$A,"="&$D$18,Data!$C:$C,"="&$B36,Data!$D:$D,"="&KillSuccess) -> 0 | S36: =COUNTIFS(Data!$A:$A,"="&$D$18,Data!$C:$C,"="&$B36,Data!$D:$D,"="&KillError) -> 0 | T36: =IF((Q36+R36+S36)=0,0,(R36-S36)/(Q36+R36+S36)) -> 0 | U36: =COUNTIFS(Data!$A:$A,"="&$D$18,Data!$C:$C,"="&$B36,Data!$D:$D,"="&AssistZero) -> 0 | V36: =COUNTIFS(Data!$A:$A,"="&$D$18,Data!$C:$C,"="&$B36,Data!$D:$D,"="&AssistSuccess) -> 0 | W36: =COUNTIFS(Data!$A:$A,"="&$D$18,Data!$C:$C,"="&$B36,Data!$D:$D,"="&AssistError) -> 0 | X36: =IF((U36+V36+W36)=0,0,(V36)/(U36+V36+W36)) -> 0 | Y36: =COUNTIFS(Data!$A:$A,"="&$D$18,Data!$C:$C,"="&$B36,Data!$D:$D,"="&BlockHalf) -> 0 | Z36: =COUNTIFS(Data!$A:$A,"="&$D$18,Data!$C:$C,"="&$B36,Data!$D:$D,"="&BlockSolo) -> 0 | AA36: =Y36*0.5+Z36 -> 0 | AB36: {=COUNTIFS(Data!$A:$A,"="&$D$18,Data!$C:$C,"="&$B36,Data!$D:$D,"="&BlockKillHalf)} -> 0 | AC36: =COUNTIFS(Data!$A:$A,"="&$D$18,Data!$C:$C,"="&$B36,Data!$D:$D,"="&BlockKillSolo) -> 0 | AD36: =AB36*0.5+AC36 -> 0 | AE36: =COUNTIFS(Data!$A:$A,"="&$D$18,Data!$C:$C,"="&$B36,Data!$D:$D,"="&GeneralError) -> 0
B37: =Legend!A18 -> k | C37: =Legend!B18&" - "&Legend!C18 -> 12 - Kaito | D37: =COUNTIFS(Data!$A:$A,"="&$D$18,Data!$C:$C,"="&B37,Data!$D:$D,"="&ServeIn) -> 0 | E37: =COUNTIFS(Data!$A:$A,"="&$D$18,Data!$C:$C,"="&B37,Data!$D:$D,"="&ServeAce) -> 0 | F37: =COUNTIFS(Data!$A:$A,"="&$D$18,Data!$C:$C,"="&B37,Data!$D:$D,"="&ServeError) -> 0 | G37: =SUM(D37:F37) -> 0 | H37: =IF((D37+E37+F37)=0,0,(D37+E37)/(D37+E37+F37)) -> 0 | I37: =COUNTIFS(Data!$A:$A,"="&$D$18,Data!$C:$C,"="&B37,Data!$D:$D,"="&Dig) -> 0 | J37: =COUNTIFS(Data!$A:$A,"="&$D$18,Data!$C:$C,"="&B37,Data!$D:$D,"="&Cover) -> 0 | K37: =J37+I37 -> 0 | L37: =COUNTIFS(Data!$A:$A,"="&$D$18,Data!$C:$C,"="&B37,Data!$D:$D,"="&Pass3) -> 0 | M37: =COUNTIFS(Data!$A:$A,"="&$D$18,Data!$C:$C,"="&B37,Data!$D:$D,"="&Pass2) -> 0 | N37: =COUNTIFS(Data!$A:$A,"="&$D$18,Data!$C:$C,"="&B37,Data!$D:$D,"="&Pass1) -> 0 | O37: =COUNTIFS(Data!$A:$A,"="&$D$18,Data!$C:$C,"="&B37,Data!$D:$D,"="&Pass0) -> 0 | P37: =L37*3+M37*2+N37*1 -> 0 | Q37: =COUNTIFS(Data!$A:$A,"="&$D$18,Data!$C:$C,"="&$B37,Data!$D:$D,"="&KillAttempt) -> 0 | R37: =COUNTIFS(Data!$A:$A,"="&$D$18,Data!$C:$C,"="&$B37,Data!$D:$D,"="&KillSuccess) -> 0 | S37: =COUNTIFS(Data!$A:$A,"="&$D$18,Data!$C:$C,"="&$B37,Data!$D:$D,"="&KillError) -> 0 | T37: =IF((Q37+R37+S37)=0,0,(R37-S37)/(Q37+R37+S37)) -> 0 | U37: =COUNTIFS(Data!$A:$A,"="&$D$18,Data!$C:$C,"="&$B37,Data!$D:$D,"="&AssistZero) -> 0 | V37: =COUNTIFS(Data!$A:$A,"="&$D$18,Data!$C:$C,"="&$B37,Data!$D:$D,"="&AssistSuccess) -> 0 | W37: =COUNTIFS(Data!$A:$A,"="&$D$18,Data!$C:$C,"="&$B37,Data!$D:$D,"="&AssistError) -> 0 | X37: =IF((U37+V37+W37)=0,0,(V37)/(U37+V37+W37)) -> 0 | Y37: =COUNTIFS(Data!$A:$A,"="&$D$18,Data!$C:$C,"="&$B37,Data!$D:$D,"="&BlockHalf) -> 0 | Z37: =COUNTIFS(Data!$A:$A,"="&$D$18,Data!$C:$C,"="&$B37,Data!$D:$D,"="&BlockSolo) -> 0 | AA37: =Y37*0.5+Z37 -> 0 | AB37: {=COUNTIFS(Data!$A:$A,"="&$D$18,Data!$C:$C,"="&$B37,Data!$D:$D,"="&BlockKillHalf)} -> 0 | AC37: =COUNTIFS(Data!$A:$A,"="&$D$18,Data!$C:$C,"="&$B37,Data!$D:$D,"="&BlockKillSolo) -> 0 | AD37: =AB37*0.5+AC37 -> 0 | AE37: =COUNTIFS(Data!$A:$A,"="&$D$18,Data!$C:$C,"="&$B37,Data!$D:$D,"="&GeneralError) -> 0
